Workbook

Sheet Допущения
A1: МОДЕЛЬ ЦЕНООБРАЗОВАНИЯ — B2B SaaS анонимизации персональных данных в документах
A2: Управленческий P&L. Все суммы в рублях без НДС. Стандарт GAAP/МСФО не применяется — это внутренняя модель принятия решения о цене.
A3: СИНИЙ = ввод (можно менять) · ЧЁРНЫЙ = формула · ЗЕЛЁНЫЙ = ссылка на другой лист · ЖЁЛТАЯ ЗАЛИВКА = допущение, требующее вашего подтверждения
A5: 1. ПЕРЕМЕННЫЕ РАСХОДЫ — ИЗМЕРЕНЫ ПРОГОНОМ РЕАЛЬНЫХ ДОКУМЕНТОВ, НЕ ДОПУЩЕНИЕ
A6: Стоимость страницы (1 800 знаков), текущая модель | B6: 0.083 | C6: ИЗМЕРЕНО | D6: Ваши данные.
A7: Стоимость страницы, дешёвая модель + кэш | B7: 0.031 | C7: ИЗМЕРЕНО | D7: Ваши данные. Планируемый переход.
A8: СТАВКА, ПРИМЕНЯЕМАЯ В МОДЕЛИ (вариант Б) | B8: =B7 -> 0.031 | C8: ПЕРЕКЛЮЧАТЕЛЬ | D8: Поставьте =B6, чтобы посчитать на текущей модели вместо дешёвой.
A10: Контроль замеров: ложатся ли три документа на одну прямую?
A11: Документ | B11: Страниц | C11: Расход, ₽ | D11: Руб/страница
A12: Короткий | B12: 1.4 | C12: 0.19 | D12: =C12/B12 -> 0.13571429
A13: Средний | B13: 9.4 | C13: 0.68 | D13: =C13/B13 -> 0.072340426
A14: Длинный | B14: 29.7 | C14: 2.49 | D14: =C14/B14 -> 0.083838384
A15: ВЫВОД по замерам | D15: Три точки НЕ ложатся на прямую: 0.136 / 0.072 / 0.084 ₽/стр. Средний документ дешевле короткого и длинного в пересчёте на страницу, чего не даёт ни одна модель вида «надбавка на документ + линейная часть». МНК по трём точкам даёт свободный член ≈0.002 ₽, то есть надбавку на документ по этим данным оценить нельзя. В модели принята чистая линейная ставка. Это безопасно: переменные расходы составляют менее 0.2% выручки, и ошибка даже в 2 раза ничего не меняет.
A17: 2. ПОСТОЯННЫЕ РАСХОДЫ — ДВА ВЗАИМОИСКЛЮЧАЮЩИХ ВАРИАНТА
A18: Вариант А: фиксированная плата за доступ к модели, ₽/мес | B18: 30000 | C18: ДАНО
A19: Вариант А: сервер и домен, ₽/мес | B19: 5000 | C19: ДАНО
A20: ВАРИАНТ А — ИТОГО ПОСТОЯННЫХ, ₽/мес | B20: =B18+B19 -> 35000
A21: Вариант А: переменная ставка за страницу, ₽/стр | B21: 0 | C21: ВЫВЕДЕНО | D21: Плата за модель фиксированная, поэтому до порога токены не тарифицируются отдельно — предельные расходы на страницу равны нулю.
A22: ВАРИАНТ Б — ИТОГО ПОСТОЯННЫХ, ₽/мес (токены поштучно + свой сервер распознавания имён) | B22: 8000 | C22: ДАНО | D22: «Около 8 000» — принято как точное значение.
A23: Вариант Б: переменная ставка за страницу, ₽/стр | B23: =B8 -> 0.031
A24: Порог, где А дешевле Б, стр/мес | B24: 361000 | C24: ДАНО
A25: Проверка порога: плата за модель / ставка текущей модели | B25: =B18/B6 -> 361445.78 | D25: Даёт 361 446 стр. Сходится с вашими 361 000 — значит порог считался против ТЕКУЩЕЙ модели (0.083 ₽/стр). На дешёвой модели порог уезжает до 30 000/0.031 = 967 742 стр/мес. Вариант А становится ещё безнадёжнее.
A27: 3. ПОДДЕРЖКА И СТОИМОСТЬ СВОЕГО ВРЕМЕНИ — ГЛАВНЫЙ БЛОК ДОПУЩЕНИЙ
A28: Стоимость часа своего времени, ₽/час | B28: 2000 | C28: ДОПУЩЕНИЕ | D28: ДОПУЩЕНИЕ. Задано вами, но не проверено: это не расход кассы, а альтернативная стоимость. Подтвердите или замените.
A29: Часов поддержки на клиента в месяц — минимум | B29: 2 | C29: ДАНО | D29: ДАНО (ваш диапазон 2–4 часа).
A30: Часов поддержки на клиента в месяц — БАЗА | B30: 3 | C30: ДОПУЩЕНИЕ | D30: ДОПУЩЕНИЕ: взята середина вашего диапазона 2–4. Статистики нет.
A31: Часов поддержки на клиента в месяц — максимум | B31: 4 | C31: ДАНО | D31: ДАНО (ваш диапазон 2–4 часа).
A32: Часов поддержки при ограниченном SLA (только почта, ответ 1 раб. день) | B32: 1 | C32: ДОПУЩЕНИЕ | D32: ДОПУЩЕНИЕ, ничем не подтверждено. На нём держится вся экономика дешёвого входного тарифа — проверьте его первым.
A33: Стоимость поддержки на клиента, база (3 ч), ₽/мес | B33: =B28*B30 -> 6000
A34: Стоимость поддержки при ограниченном SLA (1 ч), ₽/мес | B34: =B28*B32 -> 2000
A36: 4. АЛЬТЕРНАТИВА КЛИЕНТА — РУЧНАЯ ВЫЧИТКА
A37: Стоимость рабочего времени за страницу — нижняя граница, ₽/стр | B37: 20 | C37: ДАНО
A38: Стоимость рабочего времени за страницу — верхняя граница, ₽/стр | B38: 60 | C38: ДАНО
A39: Середина диапазона, ₽/стр | B39: =AVERAGE(B37:B38) -> 40
A40: Целевая доля от альтернативы (какую часть ручных расходов клиент готов платить) | B40: 0.33 | C40: ДОПУЩЕНИЕ | D40: ДОПУЩЕНИЕ. Правило «дешевле втрое» — типовой порог, при котором замена ручного процесса не требует отдельного обоснования. Рыночных данных у нас нет, число не подтверждено. Меняйте.
A41: Целевая эффективная цена, ₽/стр | B41: =B39*B40 -> 13.2
A43: 5. ПРОЧИЕ ДОПУЩЕНИЯ — ВСЕ ТРЕБУЮТ ПОДТВЕРЖДЕНИЯ
A44: Отток клиентов, % в месяц | B44: 0 | C44: ДОПУЩЕНИЕ | D44: ДОПУЩЕНИЕ: оттока нет. Заведомо оптимистично для пилотных клиентов.
A45: Расходы на продажи и маркетинг, ₽/мес | B45: 0 | C45: ДОПУЩЕНИЕ | D45: ДОПУЩЕНИЕ: продажи идут вашими руками и учтены только через стоимость часа.
A46: Налоги, ₽/мес | B46: 0 | C46: ДОПУЩЕНИЕ | D46: ДОПУЩЕНИЕ: не моделируются. Управленческий P&L, суммы без НДС.
...

Sheet Юнит_экономика
A1: ЮНИТ-ЭКОНОМИКА НА ОДНОГО КЛИЕНТА В МЕСЯЦ
A2: Столбцы B–E — конструкции ВХОДНОГО тарифа. F–G — верхние тарифы, справочно.
A3: Показатель | B3: Т1. Пилот 19 900 ₽ / 500 стр (текущий) | C3: Т1-мод. Пилот 19 900 ₽ / 1 500 стр (та же цена, квота ×3) | D3: Т2. Подписка 9 900 ₽ / 750 стр ограниченный SLA | E3: Т3. Без подписки 12 ₽/стр, мин. чек 9 900 ₽ ограниченный SLA | F3: Бизнес 49 000 ₽ / 3 000 стр (справочно) | G3: Корпоратив 149 000 ₽ / 20 000 стр (справочно) | H3: Комментарий
A4: Абонентская плата, ₽/мес | B4: 19900 | C4: 19900 | D4: 9900 | E4: 0 | F4: 49000 | G4: 149000 | H4: Т3 не имеет абонплаты — только минимальный чек.
A5: Включённая квота, стр/мес | B5: 500 | C5: 1500 | D5: 750 | E5: 0 | F5: 3000 | G5: 20000 | H5: Квота — бесплатный параметр: 1 000 лишних страниц стоят 31 ₽ токенов.
A6: Цена сверх квоты, ₽/стр | B6: 8 | C6: 8 | D6: 9 | E6: 12 | F6: 5 | G6: 3 | H6: Т2/Т3 — предложенные цифры, ДОПУЩЕНИЕ.
A7: Минимальный месячный чек, ₽ | B7: 19900 | C7: 19900 | D7: 9900 | E7: 9900 | F7: 49000 | G7: 149000 | H7: Пол выручки на клиента.
A8: Часов поддержки в месяц | B8: =Допущения!$B$30 -> 3 | C8: =Допущения!$B$30 -> 3 | D8: =Допущения!$B$32 -> 1 | E8: =Допущения!$B$32 -> 1 | F8: =Допущения!$B$30 -> 3 | G8: =Допущения!$B$31 -> 4 | H8: Ссылка на лист «Допущения». Т2 и Т3 держатся на ограниченном SLA в 1 час.
A9: Фактическое потребление, стр/мес | B9: =IF(B5>0,B5,B7/B6)*Допущения!$B$47 -> 500 | C9: =IF(C5>0,C5,C7/C6)*Допущения!$B$47 -> 1500 | D9: =IF(D5>0,D5,D7/D6)*Допущения!$B$47 -> 750 | E9: =IF(E5>0,E5,E7/E6)*Допущения!$B$47 -> 825 | F9: =IF(F5>0,F5,F7/F6)*Допущения!$B$47 -> 3000 | G9: =IF(G5>0,G5,G7/G6)*Допущения!$B$47 -> 20000 | H9: ДОПУЩЕНИЕ: клиент выбирает квоту полностью (лист «Допущения», строка 47). Для Т3 — эквивалент минимального чека.
A10: ВЫРУЧКА, ₽/мес | B10: =MAX(B7,B4+MAX(0,B9-B5)*B6) -> 19900 | C10: =MAX(C7,C4+MAX(0,C9-C5)*C6) -> 19900 | D10: =MAX(D7,D4+MAX(0,D9-D5)*D6) -> 9900 | E10: =MAX(E7,E4+MAX(0,E9-E5)*E6) -> 9900 | F10: =MAX(F7,F4+MAX(0,F9-F5)*F6) -> 49000 | G10: =MAX(G7,G4+MAX(0,G9-G5)*G6) -> 149000
A11: Эффективная цена, ₽/стр | B11: =IFERROR(B10/B9,0) -> 39.8 | C11: =IFERROR(C10/C9,0) -> 13.266667 | D11: =IFERROR(D10/D9,0) -> 13.2 | E11: =IFERROR(E10/E9,0) -> 12 | F11: =IFERROR(F10/F9,0) -> 16.333333 | G11: =IFERROR(G10/G9,0) -> 7.45 | H11: Ключевая цифра для разговора с клиентом.
A12: ВАРИАНТ Б — постоянные 8 000 ₽/мес, токены поштучно
A13: Токены, ₽/мес | B13: =-B9*Допущения!$B$23 -> -15.5 | C13: =-C9*Допущения!$B$23 -> -46.5 | D13: =-D9*Допущения!$B$23 -> -23.25 | E13: =-E9*Допущения!$B$23 -> -25.575 | F13: =-F9*Допущения!$B$23 -> -93 | G13: =-G9*Допущения!$B$23 -> -620 | H13: Меньше 0.2% выручки на любом тарифе. Переменные расходы в этой модели не являются фактором.
A14: Поддержка — своё время, ₽/мес | B14: =-B8*Допущения!$B$28 -> -6000 | C14: =-C8*Допущения!$B$28 -> -6000 | D14: =-D8*Допущения!$B$28 -> -2000 | E14: =-E8*Допущения!$B$28 -> -2000 | F14: =-F8*Допущения!$B$28 -> -6000 | G14: =-G8*Допущения!$B$28 -> -8000 | H14: ЭТО и есть реальный переменный расход. Он в 200–400 раз больше токенов.
A15: Итого прямые расходы на клиента, ₽/мес | B15: =SUM(B13:B14) -> -6015.5 | C15: =SUM(C13:C14) -> -6046.5 | D15: =SUM(D13:D14) -> -2023.25 | E15: =SUM(E13:E14) -> -2025.575 | F15: =SUM(F13:F14) -> -6093 | G15: =SUM(G13:G14) -> -8620
A16: Валовая маржа ПОЛНАЯ (со своим временем), ₽ | B16: =B10+B15 -> 13884.5 | C16: =C10+C15 -> 13853.5 | D16: =D10+D15 -> 7876.75 | E16: =E10+E15 -> 7874.425 | F16: =F10+F15 -> 42907 | G16: =G10+G15 -> 140380
A17: Валовая маржа ПОЛНАЯ, % | B17: =IFERROR(B16/B10,0) -> 0.69771357 | C17: =IFERROR(C16/C10,0) -> 0.69615578 | D17: =IFERROR(D16/D10,0) -> 0.79563131 | E17: =IFERROR(E16/E10,0) -> 0.79539646 | F17: =IFERROR(F16/F10,0) -> 0.87565306 | G17: =IFERROR(G16/G10,0) -> 0.94214765
A18: Валовая маржа ДЕНЕЖНАЯ (без своего времени), ₽ | B18: =B10+B13 -> 19884.5 | C18: =C10+C13 -> 19853.5 | D18: =D10+D13 -> 9876.75 | E18: =E10+E13 -> 9874.425 | F18: =F10+F13 -> 48907 | G18: =G10+G13 -> 148380
A19: Валовая маржа ДЕНЕЖНАЯ, % | B19: =IFERROR(B18/B10,0) -> 0.99922111 | C19: =IFERROR(C18/C10,0) -> 0.99766332 | D19: =IFERROR(D18/D10,0) -> 0.99765152 | E19: =IFERROR(E18/E10,0) -> 0.99741667 | F19: =IFERROR(F18/F10,0) -> 0.99810204 | G19: =IFERROR(G18/G10,0) -> 0.99583893 | H19: Практически 100% на любом тарифе — кассово продукт почти без себестоимости.
A20: ВАРИАНТ А — постоянные 35 000 ₽/мес, токены внутри фиксированной платы
A21: Токены, ₽/мес | B21: =-B9*Допущения!$B$21 -> 0 | C21: =-C9*Допущения!$B$21 -> 0 | D21: =-D9*Допущения!$B$21 -> 0 | E21: =-E9*Допущения!$B$21 -> 0 | F21: =-F9*Допущения!$B$21 -> 0 | G21: =-G9*Допущения!$B$21 -> 0 | H21: Ноль: плата за модель фиксированная.
A22: Валовая маржа ПОЛНАЯ, ₽ | B22: =B10+B21+B14 -> 13900 | C22: =C10+C21+C14 -> 13900 | D22: =D10+D21+D14 -> 7900 | E22: =E10+E21+E14 -> 7900 | F22: =F10+F21+F14 -> 43000 | G22: =G10+G21+G14 -> 141000
A23: Валовая маржа ПОЛНАЯ, % | B23: =IFERROR(B22/B10,0) -> 0.69849246 | C23: =IFERROR(C22/C10,0) -> 0.69849246 | D23: =IFERROR(D22/D10,0) -> 0.7979798 | E23: =IFERROR(E22/E10,0) -> 0.7979798 | F23: =IFERROR(F22/F10,0) -> 0.87755102 | G23: =IFERROR(G22/G10,0) -> 0.94630872 | H23: Выше, чем в варианте Б, ровно на стоимость токенов — то есть на копейки. Вся разница вариантов сидит в постоянных расходах.
A24: ЦЕННОСТЬ ДЛЯ КЛИЕНТА — СРАВНЕНИЕ С РУЧНОЙ ВЫЧИТКОЙ
A25: Альтернатива клиента (ручная вычитка), ₽/мес | B25: =B9*Допущения!$B$39 -> 20000 | C25: =C9*Допущения!$B$39 -> 60000 | D25: =D9*Допущения!$B$39 -> 30000 | E25: =E9*Допущения!$B$39 -> 33000 | F25: =F9*Допущения!$B$39 -> 120000 | G25: =G9*Допущения!$B$39 -> 800000 | H25: Потребление × середина диапазона 20–60 ₽/стр.
A26: Экономия клиента, ₽/мес | B26: =B25-B10 -> 100 | C26: =C25-C10 -> 40100 | D26: =D25-D10 -> 20100 | E26: =E25-E10 -> 23100 | F26: =F25-F10 -> 71000 | G26: =G25-G10 -> 651000
A27: Во сколько раз дешевле ручного труда | B27: =IFERROR(B25/B10,0) -> 1.0050251 | C27: =IFERROR(C25/C10,0) -> 3.0150754 | D27: =IFERROR(D25/D10,0) -> 3.030303 | E27: =IFERROR(E25/E10,0) -> 3.3333333 | F27: =IFERROR(F25/F10,0) -> 2.4489796 | G27: =IFERROR(G25/G10,0) -> 5.3691275
A28: Вердикт по ценности | B28: =IF(B27>=3,"Сильная",IF(B27>=1.5,"Приемлемая","СЛАБАЯ — цена сопоставима с ручным трудом")) -> СЛАБАЯ — цена сопоставима с ручным трудом | C28: =IF(C27>=3,"Сильная",IF(C27>=1.5,"Приемлемая","СЛАБАЯ — цена сопоставима с ручным трудом")) -> Сильная | D28: =IF(D27>=3,"Сильная",IF(D27>=1.5,"Приемлемая","СЛАБАЯ — цена сопоставима с ручным трудом")) -> Сильная | E28: =IF(E27>=3,"Сильная",IF(E27>=1.5,"Приемлемая","СЛАБАЯ — цена сопоставима с ручным трудом")) -> Сильная | F28: =IF(F27>=3,"Сильная",IF(F27>=1.5,"Приемлемая","СЛАБАЯ — цена сопоставима с ручным трудом")) -> Приемлемая | G28: =IF(G27>=3,"Сильная",IF(G27>=1.5,"Приемлемая","СЛАБАЯ — цена сопоставима с ручным трудом")) -> Сильная | H28: Порог «дешевле втрое» задан на листе «Допущения», строка 40 — это ДОПУЩЕНИЕ.
A29: Экономия клиента при нижней границе ручного труда (20 ₽/стр), ₽ | B29: =B9*Допущения!$B$37-B10 -> -9900 | C29: =C9*Допущения!$B$37-C10 -> 10100 | D29: =D9*Допущения!$B$37-D10 -> 5100 | E29: =E9*Допущения!$B$37-E10 -> 6600 | F29: =F9*Допущения!$B$37-F10 -> 11000 | G29: =G9*Допущения!$B$37-G10 -> 251000 | H29: Худший для нас случай: у клиента дешёвый персонал. Отрицательное значение = продавать нечего.
A31: ЧТО ЗДЕСЬ ВИДНО
A32: 1. Т1 (Пилот 19 900 / 500 стр) даёт эффективную цену 39.8 ₽/стр — это ровно середина диапазона ручной вычитки (20–60 ₽). Клиент не экономит ничего. Проблема тарифа не в абсолютной цене, а в квоте.
A33: 2. Та же цена 19 900 ₽ с квотой 1 500 стр даёт 13.3 ₽/стр — втрое дешевле ручного труда. Изменение квоты стоит нам 31 ₽ токенов в месяц. Квота — самый дешёвый рычаг в этой модели.
A34: 3. Валовая маржа во всех конструкциях 60–100%. Экономику определяют не расходы, а способность клиента заплатить и ваши часы.

Sheet Порог_цены
A1: МИНИМАЛЬНАЯ ЦЕНА ВХОДНОГО ТАРИФА — ГЛАВНЫЙ ВОПРОС
A2: Какую минимальную абонплату мы можем себе позволить, чтобы бизнес выходил в ноль. Вариант постоянных расходов Б (8 000 ₽/мес).
A4: Потребление на клиента для этого расчёта, стр/мес | B4: 500 | C4: ДОПУЩЕНИЕ | H4: Токены при 500 стр = 15.50 ₽. На результат влияния не оказывает.
A6: Клиентов одновременно | B6: Вариант Б 1 ч поддержки | C6: Вариант Б 2 ч поддержки | D6: Вариант Б 3 ч поддержки (база) | E6: Вариант Б 4 ч поддержки | F6: Вариант А 3 ч поддержки | G6: Вариант Б, 3 ч только касса | H6: Комментарий
A7: 1 | B7: =Допущения!$B$22/$A7+1*Допущения!$B$28+$B$4*Допущения!$B$23 -> 10015.5 | C7: =Допущения!$B$22/$A7+2*Допущения!$B$28+$B$4*Допущения!$B$23 -> 12015.5 | D7: =Допущения!$B$22/$A7+3*Допущения!$B$28+$B$4*Допущения!$B$23 -> 14015.5 | E7: =Допущения!$B$22/$A7+4*Допущения!$B$28+$B$4*Допущения!$B$23 -> 16015.5 | F7: =Допущения!$B$20/$A7+3*Допущения!$B$28+$B$4*Допущения!$B$21 -> 41000 | G7: =Допущения!$B$22/$A7+$B$4*Допущения!$B$23 -> 8015.5 | H7: Один пилотный клиент должен окупить ВСЁ.
A8: 2 | B8: =Допущения!$B$22/$A8+1*Допущения!$B$28+$B$4*Допущения!$B$23 -> 6015.5 | C8: =Допущения!$B$22/$A8+2*Допущения!$B$28+$B$4*Допущения!$B$23 -> 8015.5 | D8: =Допущения!$B$22/$A8+3*Допущения!$B$28+$B$4*Допущения!$B$23 -> 10015.5 | E8: =Допущения!$B$22/$A8+4*Допущения!$B$28+$B$4*Допущения!$B$23 -> 12015.5 | F8: =Допущения!$B$20/$A8+3*Допущения!$B$28+$B$4*Допущения!$B$21 -> 23500 | G8: =Допущения!$B$22/$A8+$B$4*Допущения!$B$23 -> 4015.5
A9: 3 | B9: =Допущения!$B$22/$A9+1*Допущения!$B$28+$B$4*Допущения!$B$23 -> 4682.1667 | C9: =Допущения!$B$22/$A9+2*Допущения!$B$28+$B$4*Допущения!$B$23 -> 6682.1667 | D9: =Допущения!$B$22/$A9+3*Допущения!$B$28+$B$4*Допущения!$B$23 -> 8682.1667 | E9: =Допущения!$B$22/$A9+4*Допущения!$B$28+$B$4*Допущения!$B$23 -> 10682.167 | F9: =Допущения!$B$20/$A9+3*Допущения!$B$28+$B$4*Допущения!$B$21 -> 17666.667 | G9: =Допущения!$B$22/$A9+$B$4*Допущения!$B$23 -> 2682.1667
A10: 4 | B10: =Допущения!$B$22/$A10+1*Допущения!$B$28+$B$4*Допущения!$B$23 -> 4015.5 | C10: =Допущения!$B$22/$A10+2*Допущения!$B$28+$B$4*Допущения!$B$23 -> 6015.5 | D10: =Допущения!$B$22/$A10+3*Допущения!$B$28+$B$4*Допущения!$B$23 -> 8015.5 | E10: =Допущения!$B$22/$A10+4*Допущения!$B$28+$B$4*Допущения!$B$23 -> 10015.5 | F10: =Допущения!$B$20/$A10+3*Допущения!$B$28+$B$4*Допущения!$B$21 -> 14750 | G10: =Допущения!$B$22/$A10+$B$4*Допущения!$B$23 -> 2015.5
A11: 5 | B11: =Допущения!$B$22/$A11+1*Допущения!$B$28+$B$4*Допущения!$B$23 -> 3615.5 | C11: =Допущения!$B$22/$A11+2*Допущения!$B$28+$B$4*Допущения!$B$23 -> 5615.5 | D11: =Допущения!$B$22/$A11+3*Допущения!$B$28+$B$4*Допущения!$B$23 -> 7615.5 | E11: =Допущения!$B$22/$A11+4*Допущения!$B$28+$B$4*Допущения!$B$23 -> 9615.5 | F11: =Допущения!$B$20/$A11+3*Допущения!$B$28+$B$4*Допущения!$B$21 -> 13000 | G11: =Допущения!$B$22/$A11+$B$4*Допущения!$B$23 -> 1615.5
A12: 7 | B12: =Допущения!$B$22/$A12+1*Допущения!$B$28+$B$4*Допущения!$B$23 -> 3158.3571 | C12: =Допущения!$B$22/$A12+2*Допущения!$B$28+$B$4*Допущения!$B$23 -> 5158.3571 | D12: =Допущения!$B$22/$A12+3*Допущения!$B$28+$B$4*Допущения!$B$23 -> 7158.3571 | E12: =Допущения!$B$22/$A12+4*Допущения!$B$28+$B$4*Допущения!$B$23 -> 9158.3571 | F12: =Допущения!$B$20/$A12+3*Допущения!$B$28+$B$4*Допущения!$B$21 -> 11000 | G12: =Допущения!$B$22/$A12+$B$4*Допущения!$B$23 -> 1158.3571
A13: 10 | B13: =Допущения!$B$22/$A13+1*Допущения!$B$28+$B$4*Допущения!$B$23 -> 2815.5 | C13: =Допущения!$B$22/$A13+2*Допущения!$B$28+$B$4*Допущения!$B$23 -> 4815.5 | D13: =Допущения!$B$22/$A13+3*Допущения!$B$28+$B$4*Допущения!$B$23 -> 6815.5 | E13: =Допущения!$B$22/$A13+4*Допущения!$B$28+$B$4*Допущения!$B$23 -> 8815.5 | F13: =Допущения!$B$20/$A13+3*Допущения!$B$28+$B$4*Допущения!$B$21 -> 9500 | G13: =Допущения!$B$22/$A13+$B$4*Допущения!$B$23 -> 815.5 | H13: Устойчивый режим.
A15: КАК ЧИТАТЬ ТАБЛИЦУ
A16: Каждая ячейка — минимальная абонплата на клиента, при которой вы выходите ровно в ноль: постоянные расходы делятся на число клиентов, плюс ваша поддержка этого клиента, плюс его токены.
A17: Столбцы B–E: своё время считается расходом (полная окупаемость). Столбец G: своё время не считается — это чистая касса. Разрыв между D и G (6 000 ₽) — цена ваших трёх часов.
A18: Столбец F показывает, во что обходится вариант А: при одном клиенте порог 41 000 ₽ против 14 016 ₽ у варианта Б. Вариант А на входных объёмах нежизнеспособен, ваш вывод подтверждается с большим запасом.
A19: ГЛАВНЫЙ ОТВЕТ: при варианте Б и ОДНОМ клиенте абсолютный пол — 10 016 ₽/мес при 1 часе поддержки, 14 016 ₽ при 3 часах, 16 016 ₽ при 4 часах. Кассовый пол (без учёта своего времени) — 8 016 ₽/мес.
A20: Отсюда: 19 900 ₽ НЕ является завышенной ценой с точки зрения расходов — она всего в 1.2–2.0 раза выше порога окупаемости. Пространство для снижения есть, но оно узкое и целиком съедается часами поддержки.

Sheet PL_12мес
A1: P&L НА 12 МЕСЯЦЕВ — 3 СЦЕНАРИЯ × 2 ВАРИАНТА ПОСТОЯННЫХ РАСХОДОВ
A2: Постепенный разгон: клиенты подключаются в течение года. Строка «Клиентов» — синяя, меняйте свободно.
A4: ТАРИФ ДЛЯ РАСЧЁТА (1=Пилот 19900/500 · 2=19900/1500 · 3=9900/750 · 4=без подписки · 5=Бизнес · 6=Корпоратив) | B4: 3 | O4: Переключатель. По умолчанию 3 — рекомендуемый входной тариф.
A5: Выручка на клиента, ₽/мес | B5: =INDEX(Юнит_экономика!$B$10:$G$10,$B$4) -> 9900
A6: Токены на клиента (вариант Б), ₽/мес | B6: =-INDEX(Юнит_экономика!$B$13:$G$13,$B$4) -> 23.25
A7: Поддержка на клиента (своё время), ₽/мес | B7: =-INDEX(Юнит_экономика!$B$14:$G$14,$B$4) -> 2000
A9: СЦЕНАРИЙ 1 — ПЕССИМИСТИЧНЫЙ: 2 клиента к 12-му месяцу | O9: График подключения — ДОПУЩЕНИЕ. Данных о конверсии и спросе нет.
A10: Месяц | B10: М1 | C10: М2 | D10: М3 | E10: М4 | F10: М5 | G10: М6 | H10: М7 | I10: М8 | J10: М9 | K10: М10 | L10: М11 | M10: М12 | N10: ИТОГО за год
A11: Клиентов на конец месяца | B11: 0 | C11: 0 | D11: 1 | E11: 1 | F11: 1 | G11: 1 | H11: 1 | I11: 2 | J11: 2 | K11: 2 | L11: 2 | M11: 2 | N11: =MAX(B11:M11) -> 2 | O11: Синие ячейки — ваш ввод.
A12: Выручка | B12: =$B$5*B11 -> 0 | C12: =$B$5*C11 -> 0 | D12: =$B$5*D11 -> 9900 | E12: =$B$5*E11 -> 9900 | F12: =$B$5*F11 -> 9900 | G12: =$B$5*G11 -> 9900 | H12: =$B$5*H11 -> 9900 | I12: =$B$5*I11 -> 19800 | ... M12: =$B$5*M11 -> 19800 | N12: =SUM(B12:M12) -> 148500
A13: Токены (вариант Б) | B13: =-$B$6*B11 -> 0 | C13: =-$B$6*C11 -> 0 | D13: =-$B$6*D11 -> -23.25 | E13: =-$B$6*E11 -> -23.25 | F13: =-$B$6*F11 -> -23.25 | G13: =-$B$6*G11 -> -23.25 | H13: =-$B$6*H11 -> -23.25 | I13: =-$B$6*I11 -> -46.5 | ... M13: =-$B$6*M11 -> -46.5 | N13: =SUM(B13:M13) -> -348.75
A14: Постоянные расходы, вариант Б | B14: =-Допущения!$B$22 -> -8000 | C14: =-Допущения!$B$22 -> -8000 | D14: =-Допущения!$B$22 -> -8000 | E14: =-Допущения!$B$22 -> -8000 | F14: =-Допущения!$B$22 -> -8000 | G14: =-Допущения!$B$22 -> -8000 | H14: =-Допущения!$B$22 -> -8000 | I14: =-Допущения!$B$22 -> -8000 | ... M14: =-Допущения!$B$22 -> -8000 | N14: =SUM(B14:M14) -> -96000
A15: Продажи и маркетинг | B15: =-Допущения!$B$45 -> 0 | C15: =-Допущения!$B$45 -> 0 | D15: =-Допущения!$B$45 -> 0 | E15: =-Допущения!$B$45 -> 0 | F15: =-Допущения!$B$45 -> 0 | G15: =-Допущения!$B$45 -> 0 | H15: =-Допущения!$B$45 -> 0 | I15: =-Допущения!$B$45 -> 0 | ... M15: =-Допущения!$B$45 -> 0 | N15: =SUM(B15:M15) -> 0
A16: EBITDA ДЕНЕЖНАЯ, вариант Б | B16: =SUM(B12:B15) -> -8000 | C16: =SUM(C12:C15) -> -8000 | D16: =SUM(D12:D15) -> 1876.75 | E16: =SUM(E12:E15) -> 1876.75 | F16: =SUM(F12:F15) -> 1876.75 | G16: =SUM(G12:G15) -> 1876.75 | H16: =SUM(H12:H15) -> 1876.75 | I16: =SUM(I12:I15) -> 11753.5 | ... M16: =SUM(M12:M15) -> 11753.5 | N16: =SUM(B16:M16) -> 52151.25
A17: Своё время на поддержку | B17: =-$B$7*B11 -> 0 | C17: =-$B$7*C11 -> 0 | D17: =-$B$7*D11 -> -2000 | E17: =-$B$7*E11 -> -2000 | F17: =-$B$7*F11 -> -2000 | G17: =-$B$7*G11 -> -2000 | H17: =-$B$7*H11 -> -2000 | I17: =-$B$7*I11 -> -4000 | ... M17: =-$B$7*M11 -> -4000 | N17: =SUM(B17:M17) -> -30000
A18: EBITDA ПОЛНАЯ, вариант Б | B18: =B16+B17 -> -8000 | C18: =C16+C17 -> -8000 | D18: =D16+D17 -> -123.25 | E18: =E16+E17 -> -123.25 | F18: =F16+F17 -> -123.25 | G18: =G16+G17 -> -123.25 | H18: =H16+H17 -> -123.25 | I18: =I16+I17 -> 7753.5 | ... M18: =M16+M17 -> 7753.5 | N18: =SUM(B18:M18) -> 22151.25
A19: Накопленная EBITDA полная, вариант Б | B19: =B18 -> -8000 | C19: =B19+C18 -> -16000 | D19: =C19+D18 -> -16123.25 | E19: =D19+E18 -> -16246.5 | F19: =E19+F18 -> -16369.75 | G19: =F19+G18 -> -16493 | H19: =G19+H18 -> -16616.25 | I19: =H19+I18 -> -8862.75 | J19: =I19+J18 -> -1109.25 | ... M19: =L19+M18 -> 22151.25 | N19: =M19 -> 22151.25
A20: Токены (вариант А) | B20: =-Допущения!$B$21*Юнит_экономика!$B$9*B11 -> 0 | C20: =-Допущения!$B$21*Юнит_экономика!$B$9*C11 -> 0 | D20: =-Допущения!$B$21*Юнит_экономика!$B$9*D11 -> 0 | E20: =-Допущения!$B$21*Юнит_экономика!$B$9*E11 -> 0 | F20: =-Допущения!$B$21*Юнит_экономика!$B$9*F11 -> 0 | G20: =-Допущения!$B$21*Юнит_экономика!$B$9*G11 -> 0 | H20: =-Допущения!$B$21*Юнит_экономика!$B$9*H11 -> 0 | I20: =-Допущения!$B$21*Юнит_экономика!$B$9*I11 -> 0 | ... M20: =-Допущения!$B$21*Юнит_экономика!$B$9*M11 -> 0 | N20: =SUM(B20:M20) -> 0
A21: Постоянные расходы, вариант А | B21: =-Допущения!$B$20 -> -35000 | C21: =-Допущения!$B$20 -> -35000 | D21: =-Допущения!$B$20 -> -35000 | E21: =-Допущения!$B$20 -> -35000 | F21: =-Допущения!$B$20 -> -35000 | G21: =-Допущения!$B$20 -> -35000 | H21: =-Допущения!$B$20 -> -35000 | I21: =-Допущения!$B$20 -> -35000 | ... M21: =-Допущения!$B$20 -> -35000 | N21: =SUM(B21:M21) -> -420000
A22: EBITDA ДЕНЕЖНАЯ, вариант А | B22: =B12+B20+B21+B15 -> -35000 | C22: =C12+C20+C21+C15 -> -35000 | D22: =D12+D20+D21+D15 -> -25100 | E22: =E12+E20+E21+E15 -> -25100 | F22: =F12+F20+F21+F15 -> -25100 | G22: =G12+G20+G21+G15 -> -25100 | H22: =H12+H20+H21+H15 -> -25100 | I22: =I12+I20+I21+I15 -> -15200 | ... M22: =M12+M20+M21+M15 -> -15200 | N22: =SUM(B22:M22) -> -271500
A23: EBITDA ПОЛНАЯ, вариант А | B23: =B22+B17 -> -35000 | C23: =C22+C17 -> -35000 | D23: =D22+D17 -> -27100 | E23: =E22+E17 -> -27100 | F23: =F22+F17 -> -27100 | G23: =G22+G17 -> -27100 | H23: =H22+H17 -> -27100 | I23: =I22+I17 -> -19200 | ... M23: =M22+M17 -> -19200 | N23: =SUM(B23:M23) -> -301500
A24: Накопленная EBITDA полная, вариант А | B24: =B23 -> -35000 | C24: =B24+C23 -> -70000 | D24: =C24+D23 -> -97100 | E24: =D24+E23 -> -124200 | F24: =E24+F23 -> -151300 | G24: =F24+G23 -> -178400 | H24: =G24+H23 -> -205500 | I24: =H24+I23 -> -224700 | J24: =I24+J23 -> -243900 | ... M24: =L24+M23 -> -301500 | N24: =M24 -> -301500
A25: Разница Б минус А, ₽ | B25: =B18-B23 -> 27000 | C25: =C18-C23 -> 27000 | D25: =D18-D23 -> 26976.75 | E25: =E18-E23 -> 26976.75 | F25: =F18-F23 -> 26976.75 | G25: =G18-G23 -> 26976.75 | H25: =H18-H23 -> 26976.75 | I25: =I18-I23 -> 26953.5 | ... M25: =M18-M23 -> 26953.5 | N25: =SUM(B25:M25) -> 323651.25
A26: Месяц выхода в плюс (полная EBITDA, вариант Б) | B26: =IF(COUNTIF(B18:M18,">0")=0,"не достигнут",13-COUNTIF(B18:M18,">0")) -> 8 | D26: Месяц выхода в плюс (полная EBITDA, вариант А) | F26: =IF(COUNTIF(B23:M23,">0")=0,"не достигнут",13-COUNTIF(B23:M23,">0")) -> не достигнут | O26: Формула опирается на то, что число клиентов только растёт (оттока в модели нет).
A28: СЦЕНАРИЙ 2 — БАЗОВЫЙ: 4 клиента к 12-му месяцу | O28: График подключения — ДОПУЩЕНИЕ. Данных о конверсии и спросе нет.
A29: Месяц | B29: М1 | C29: М2 | D29: М3 | E29: М4 | F29: М5 | G29: М6 | H29: М7 | I29: М8 | J29: М9 | K29: М10 | L29: М11 | M29: М12 | N29: ИТОГО за год
A30: Клиентов на конец месяца | B30: 0 | C30: 1 | D30: 1 | E30: 2 | F30: 2 | G30: 2 | H30: 3 | I30: 3 | J30: 3 | K30: 4 | L30: 4 | M30: 4 | N30: =MAX(B30:M30) -> 4 | O30: Синие ячейки — ваш ввод.
A31: Выручка | B31: =$B$5*B30 -> 0 | C31: =$B$5*C30 -> 9900 | D31: =$B$5*D30 -> 9900 | E31: =$B$5*E30 -> 19800 | F31: =$B$5*F30 -> 19800 | G31: =$B$5*G30 -> 19800 | H31: =$B$5*H30 -> 29700 | I31: =$B$5*I30 -> 29700 | ... M31: =$B$5*M30 -> 39600 | N31: =SUM(B31:M31) -> 287100
A32: Токены (вариант Б) | B32: =-$B$6*B30 -> 0 | C32: =-$B$6*C30 -> -23.25 | D32: =-$B$6*D30 -> -23.25 | E32: =-$B$6*E30 -> -46.5 | F32: =-$B$6*F30 -> -46.5 | G32: =-$B$6*G30 -> -46.5 | H32: =-$B$6*H30 -> -69.75 | I32: =-$B$6*I30 -> -69.75 | ... M32: =-$B$6*M30 -> -93 | N32: =SUM(B32:M32) -> -674.25
A33: Постоянные расходы, вариант Б | B33: =-Допущения!$B$22 -> -8000 | C33: =-Допущения!$B$22 -> -8000 | D33: =-Допущения!$B$22 -> -8000 | E33: =-Допущения!$B$22 -> -8000 | F33: =-Допущения!$B$22 -> -8000 | G33: =-Допущения!$B$22 -> -8000 | H33: =-Допущения!$B$22 -> -8000 | I33: =-Допущения!$B$22 -> -8000 | ... M33: =-Допущения!$B$22 -> -8000 | N33: =SUM(B33:M33) -> -96000
A34: Продажи и маркетинг | B34: =-Допущения!$B$45 -> 0 | C34: =-Допущения!$B$45 -> 0 | D34: =-Допущения!$B$45 -> 0 | E34: =-Допущения!$B$45 -> 0 | F34: =-Допущения!$B$45 -> 0 | G34: =-Допущения!$B$45 -> 0 | H34: =-Допущения!$B$45 -> 0 | I34: =-Допущения!$B$45 -> 0 | ... M34: =-Допущения!$B$45 -> 0 | N34: =SUM(B34:M34) -> 0
A35: EBITDA ДЕНЕЖНАЯ, вариант Б | B35: =SUM(B31:B34) -> -8000 | C35: =SUM(C31:C34) -> 1876.75 | D35: =SUM(D31:D34) -> 1876.75 | E35: =SUM(E31:E34) -> 11753.5 | F35: =SUM(F31:F34) -> 11753.5 | G35: =SUM(G31:G34) -> 11753.5 | H35: =SUM(H31:H34) -> 21630.25 | I35: =SUM(I31:I34) -> 21630.25 | ... M35: =SUM(M31:M34) -> 31507 | N35: =SUM(B35:M35) -> 190425.75
A36: Своё время на поддержку | B36: =-$B$7*B30 -> 0 | C36: =-$B$7*C30 -> -2000 | D36: =-$B$7*D30 -> -2000 | E36: =-$B$7*E30 -> -4000 | F36: =-$B$7*F30 -> -4000 | G36: =-$B$7*G30 -> -4000 | H36: =-$B$7*H30 -> -6000 | I36: =-$B$7*I30 -> -6000 | ... M36: =-$B$7*M30 -> -8000 | N36: =SUM(B36:M36) -> -58000
A37: EBITDA ПОЛНАЯ, вариант Б | B37: =B35+B36 -> -8000 | C37: =C35+C36 -> -123.25 | D37: =D35+D36 -> -123.25 | E37: =E35+E36 -> 7753.5 | F37: =F35+F36 -> 7753.5 | G37: =G35+G36 -> 7753.5 | H37: =H35+H36 -> 15630.25 | I37: =I35+I36 -> 15630.25 | ... M37: =M35+M36 -> 23507 | N37: =SUM(B37:M37) -> 132425.75
A38: Накопленная EBITDA полная, вариант Б | B38: =B37 -> -8000 | C38: =B38+C37 -> -8123.25 | D38: =C38+D37 -> -8246.5 | E38: =D38+E37 -> -493 | F38: =E38+F37 -> 7260.5 | G38: =F38+G37 -> 15014 | H38: =G38+H37 -> 30644.25 | I38: =H38+I37 -> 46274.5 | J38: =I38+J37 -> 61904.75 | ... M38: =L38+M37 -> 132425.75 | N38: =M38 -> 132425.75
A39: Токены (вариант А) | B39: =-Допущения!$B$21*Юнит_экономика!$B$9*B30 -> 0 | C39: =-Допущения!$B$21*Юнит_экономика!$B$9*C30 -> 0 | D39: =-Допущения!$B$21*Юнит_экономика!$B$9*D30 -> 0 | E39: =-Допущения!$B$21*Юнит_экономика!$B$9*E30 -> 0 | F39: =-Допущения!$B$21*Юнит_экономика!$B$9*F30 -> 0 | G39: =-Допущения!$B$21*Юнит_экономика!$B$9*G30 -> 0 | H39: =-Допущения!$B$21*Юнит_экономика!$B$9*H30 -> 0 | I39: =-Допущения!$B$21*Юнит_экономика!$B$9*I30 -> 0 | ... M39: =-Допущения!$B$21*Юнит_экономика!$B$9*M30 -> 0 | N39: =SUM(B39:M39) -> 0
A40: Постоянные расходы, вариант А | B40: =-Допущения!$B$20 -> -35000 | C40: =-Допущения!$B$20 -> -35000 | D40: =-Допущения!$B$20 -> -35000 | E40: =-Допущения!$B$20 -> -35000 | F40: =-Допущения!$B$20 -> -35000 | G40: =-Допущения!$B$20 -> -35000 | H40: =-Допущения!$B$20 -> -35000 | I40: =-Допущения!$B$20 -> -35000 | ... M40: =-Допущения!$B$20 -> -35000 | N40: =SUM(B40:M40) -> -420000
A41: EBITDA ДЕНЕЖНАЯ, вариант А | B41: =B31+B39+B40+B34 -> -35000 | C41: =C31+C39+C40+C34 -> -25100 | D41: =D31+D39+D40+D34 -> -25100 | E41: =E31+E39+E40+E34 -> -15200 | F41: =F31+F39+F40+F34 -> -15200 | G41: =G31+G39+G40+G34 -> -15200 | H41: =H31+H39+H40+H34 -> -5300 | I41: =I31+I39+I40+I34 -> -5300 | ... M41: =M31+M39+M40+M34 -> 4600 | N41: =SUM(B41:M41) -> -132900
A42: EBITDA ПОЛНАЯ, вариант А | B42: =B41+B36 -> -35000 | C42: =C41+C36 -> -27100 | D42: =D41+D36 -> -27100 | E42: =E41+E36 -> -19200 | F42: =F41+F36 -> -19200 | G42: =G41+G36 -> -19200 | H42: =H41+H36 -> -11300 | I42: =I41+I36 -> -11300 | ... M42: =M41+M36 -> -3400 | N42: =SUM(B42:M42) -> -190900
A43: Накопленная EBITDA полная, вариант А | B43: =B42 -> -35000 | C43: =B43+C42 -> -62100 | D43: =C43+D42 -> -89200 | E43: =D43+E42 -> -108400 | F43: =E43+F42 -> -127600 | G43: =F43+G42 -> -146800 | H43: =G43+H42 -> -158100 | I43: =H43+I42 -> -169400 | J43: =I43+J42 -> -180700 | ... M43: =L43+M42 -> -190900 | N43: =M43 -> -190900
...

Sheet Безубыточность
A1: ТОЧКА БЕЗУБЫТОЧНОСТИ В ЧИСЛЕ КЛИЕНТОВ
A2: Сколько клиентов нужно, чтобы покрыть постоянные расходы. От сценария не зависит — сценарий отвечает лишь на вопрос, дойдём ли мы до этого числа.
A4: Тариф | B4: Выручка /клиент | C4: Токены /клиент | D4: Поддержка /клиент | E4: Вклад ПОЛНЫЙ вар. Б | F4: Клиентов вар. Б полная | G4: Вклад ДЕНЕЖНЫЙ вар. Б | H4: Клиентов вар. Б касса | I4: Вклад ПОЛНЫЙ вар. А | J4: Клиентов вар. А полная | L4: Комментарий
A5: Т1. Пилот 19 900 / 500 | B5: =Юнит_экономика!B10 -> 19900 | C5: =Юнит_экономика!B13 -> -15.5 | D5: =Юнит_экономика!B14 -> -6000 | E5: =B5+C5+D5 -> 13884.5 | F5: =IF(E5<=0,"никогда",ROUNDUP(Допущения!$B$22/E5,0)) -> 1 | G5: =B5+C5 -> 19884.5 | H5: =IF(G5<=0,"никогда",ROUNDUP(Допущения!$B$22/G5,0)) -> 1 | I5: =B5+D5 -> 13900 | J5: =IF(I5<=0,"никогда",ROUNDUP(Допущения!$B$20/I5,0)) -> 3 | L5: Текущее предложение.
A6: Т1-мод. 19 900 / 1 500 | B6: =Юнит_экономика!C10 -> 19900 | C6: =Юнит_экономика!C13 -> -46.5 | D6: =Юнит_экономика!C14 -> -6000 | E6: =B6+C6+D6 -> 13853.5 | F6: =IF(E6<=0,"никогда",ROUNDUP(Допущения!$B$22/E6,0)) -> 1 | G6: =B6+C6 -> 19853.5 | H6: =IF(G6<=0,"никогда",ROUNDUP(Допущения!$B$22/G6,0)) -> 1 | I6: =B6+D6 -> 13900 | J6: =IF(I6<=0,"никогда",ROUNDUP(Допущения!$B$20/I6,0)) -> 3 | L6: Та же цена, квота ×3.
A7: Т2. 9 900 / 750, SLA 1 ч | B7: =Юнит_экономика!D10 -> 9900 | C7: =Юнит_экономика!D13 -> -23.25 | D7: =Юнит_экономика!D14 -> -2000 | E7: =B7+C7+D7 -> 7876.75 | F7: =IF(E7<=0,"никогда",ROUNDUP(Допущения!$B$22/E7,0)) -> 2 | G7: =B7+C7 -> 9876.75 | H7: =IF(G7<=0,"никогда",ROUNDUP(Допущения!$B$22/G7,0)) -> 1 | I7: =B7+D7 -> 7900 | J7: =IF(I7<=0,"никогда",ROUNDUP(Допущения!$B$20/I7,0)) -> 5 | L7: РЕКОМЕНДУЕТСЯ.
A8: Т3. Без подписки, мин. чек 9 900 | B8: =Юнит_экономика!E10 -> 9900 | C8: =Юнит_экономика!E13 -> -25.575 | D8: =Юнит_экономика!E14 -> -2000 | E8: =B8+C8+D8 -> 7874.425 | F8: =IF(E8<=0,"никогда",ROUNDUP(Допущения!$B$22/E8,0)) -> 2 | G8: =B8+C8 -> 9874.425 | H8: =IF(G8<=0,"никогда",ROUNDUP(Допущения!$B$22/G8,0)) -> 1 | I8: =B8+D8 -> 7900 | J8: =IF(I8<=0,"никогда",ROUNDUP(Допущения!$B$20/I8,0)) -> 5 | L8: Понятен клиенту, но выручка непредсказуема.
A9: Бизнес 49 000 / 3 000 | B9: =Юнит_экономика!F10 -> 49000 | C9: =Юнит_экономика!F13 -> -93 | D9: =Юнит_экономика!F14 -> -6000 | E9: =B9+C9+D9 -> 42907 | F9: =IF(E9<=0,"никогда",ROUNDUP(Допущения!$B$22/E9,0)) -> 1 | G9: =B9+C9 -> 48907 | H9: =IF(G9<=0,"никогда",ROUNDUP(Допущения!$B$22/G9,0)) -> 1 | I9: =B9+D9 -> 43000 | J9: =IF(I9<=0,"никогда",ROUNDUP(Допущения!$B$20/I9,0)) -> 1
A10: Корпоратив 149 000 / 20 000 | B10: =Юнит_экономика!G10 -> 149000 | C10: =Юнит_экономика!G13 -> -620 | D10: =Юнит_экономика!G14 -> -8000 | E10: =B10+C10+D10 -> 140380 | F10: =IF(E10<=0,"никогда",ROUNDUP(Допущения!$B$22/E10,0)) -> 1 | G10: =B10+C10 -> 148380 | H10: =IF(G10<=0,"никогда",ROUNDUP(Допущения!$B$22/G10,0)) -> 1 | I10: =B10+D10 -> 141000 | J10: =IF(I10<=0,"никогда",ROUNDUP(Допущения!$B$20/I10,0)) -> 1
A12: ДОСТИГАЕТСЯ ЛИ БЕЗУБЫТОЧНОСТЬ В СЦЕНАРИИ (по числу клиентов на 12-й месяц)
A13: Сценарий | B13: Клиентов на М12 | C13: Т1. Пилот 19 900 / 500 | D13: Т1-мод. 19 900 / 1 500 | E13: Т2. 9 900 / 750, SLA 1 ч | F13: Т3. Без подписки, мин. чек 9 900 | G13: Бизнес 49 000 / 3 000 | H13: Корпоратив 149 000 / 20 000
A14: Пессимистичный | B14: 2 | C14: =IF(ISNUMBER($F$5),IF($B14>=$F$5,"ДА","НЕТ"),"НЕТ") -> ДА | D14: =IF(ISNUMBER($F$6),IF($B14>=$F$6,"ДА","НЕТ"),"НЕТ") -> ДА | E14: =IF(ISNUMBER($F$7),IF($B14>=$F$7,"ДА","НЕТ"),"НЕТ") -> ДА | F14: =IF(ISNUMBER($F$8),IF($B14>=$F$8,"ДА","НЕТ"),"НЕТ") -> ДА | G14: =IF(ISNUMBER($F$9),IF($B14>=$F$9,"ДА","НЕТ"),"НЕТ") -> ДА | H14: =IF(ISNUMBER($F$10),IF($B14>=$F$10,"ДА","НЕТ"),"НЕТ") -> ДА | L14: Вариант Б, полная окупаемость со своим временем.
A15: Базовый | B15: 4 | C15: =IF(ISNUMBER($F$5),IF($B15>=$F$5,"ДА","НЕТ"),"НЕТ") -> ДА | D15: =IF(ISNUMBER($F$6),IF($B15>=$F$6,"ДА","НЕТ"),"НЕТ") -> ДА | E15: =IF(ISNUMBER($F$7),IF($B15>=$F$7,"ДА","НЕТ"),"НЕТ") -> ДА | F15: =IF(ISNUMBER($F$8),IF($B15>=$F$8,"ДА","НЕТ"),"НЕТ") -> ДА | G15: =IF(ISNUMBER($F$9),IF($B15>=$F$9,"ДА","НЕТ"),"НЕТ") -> ДА | H15: =IF(ISNUMBER($F$10),IF($B15>=$F$10,"ДА","НЕТ"),"НЕТ") -> ДА
A16: Оптимистичный | B16: 10 | C16: =IF(ISNUMBER($F$5),IF($B16>=$F$5,"ДА","НЕТ"),"НЕТ") -> ДА | D16: =IF(ISNUMBER($F$6),IF($B16>=$F$6,"ДА","НЕТ"),"НЕТ") -> ДА | E16: =IF(ISNUMBER($F$7),IF($B16>=$F$7,"ДА","НЕТ"),"НЕТ") -> ДА | F16: =IF(ISNUMBER($F$8),IF($B16>=$F$8,"ДА","НЕТ"),"НЕТ") -> ДА | G16: =IF(ISNUMBER($F$9),IF($B16>=$F$9,"ДА","НЕТ"),"НЕТ") -> ДА | H16: =IF(ISNUMBER($F$10),IF($B16>=$F$10,"ДА","НЕТ"),"НЕТ") -> ДА
A18: То же для ВАРИАНТА А (постоянные 35 000 ₽)
A19: Пессимистичный | B19: =B14 -> 2 | C19: =IF(ISNUMBER($J$5),IF($B19>=$J$5,"ДА","НЕТ"),"НЕТ") -> НЕТ | D19: =IF(ISNUMBER($J$6),IF($B19>=$J$6,"ДА","НЕТ"),"НЕТ") -> НЕТ | E19: =IF(ISNUMBER($J$7),IF($B19>=$J$7,"ДА","НЕТ"),"НЕТ") -> НЕТ | F19: =IF(ISNUMBER($J$8),IF($B19>=$J$8,"ДА","НЕТ"),"НЕТ") -> НЕТ | G19: =IF(ISNUMBER($J$9),IF($B19>=$J$9,"ДА","НЕТ"),"НЕТ") -> ДА | H19: =IF(ISNUMBER($J$10),IF($B19>=$J$10,"ДА","НЕТ"),"НЕТ") -> ДА
A20: Базовый | B20: =B15 -> 4 | C20: =IF(ISNUMBER($J$5),IF($B20>=$J$5,"ДА","НЕТ"),"НЕТ") -> ДА | D20: =IF(ISNUMBER($J$6),IF($B20>=$J$6,"ДА","НЕТ"),"НЕТ") -> ДА | E20: =IF(ISNUMBER($J$7),IF($B20>=$J$7,"ДА","НЕТ"),"НЕТ") -> НЕТ | F20: =IF(ISNUMBER($J$8),IF($B20>=$J$8,"ДА","НЕТ"),"НЕТ") -> НЕТ | G20: =IF(ISNUMBER($J$9),IF($B20>=$J$9,"ДА","НЕТ"),"НЕТ") -> ДА | H20: =IF(ISNUMBER($J$10),IF($B20>=$J$10,"ДА","НЕТ"),"НЕТ") -> ДА
A21: Оптимистичный | B21: =B16 -> 10 | C21: =IF(ISNUMBER($J$5),IF($B21>=$J$5,"ДА","НЕТ"),"НЕТ") -> ДА | D21: =IF(ISNUMBER($J$6),IF($B21>=$J$6,"ДА","НЕТ"),"НЕТ") -> ДА | E21: =IF(ISNUMBER($J$7),IF($B21>=$J$7,"ДА","НЕТ"),"НЕТ") -> ДА | F21: =IF(ISNUMBER($J$8),IF($B21>=$J$8,"ДА","НЕТ"),"НЕТ") -> ДА | G21: =IF(ISNUMBER($J$9),IF($B21>=$J$9,"ДА","НЕТ"),"НЕТ") -> ДА | H21: =IF(ISNUMBER($J$10),IF($B21>=$J$10,"ДА","НЕТ"),"НЕТ") -> ДА

Sheet Чувствительность
A1: ЧУВСТВИТЕЛЬНОСТЬ
A3: БЛОК 1. КЛИЕНТ ВЫБИРАЕТ КВОТУ В 10 РАЗ БОЛЬШЕ
A4: Показатель | B4: Т1. Пилот 19 900 ₽ / 500 стр (текущий) | C4: Т1-мод. Пилот 19 900 ₽ / 1 500 стр (та же цена, квота ×3) | D4: Т2. Подписка 9 900 ₽ / 750 стр ограниченный SLA | E4: Т3. Без подписки 12 ₽/стр, мин. чек 9 900 ₽ ограниченный SLA | F4: Бизнес 49 000 ₽ / 3 000 стр (справочно) | G4: Корпоратив 149 000 ₽ / 20 000 стр (справочно) | H4: Комментарий
A5: Множитель потребления | B5: 10 | C5: =$B$5 -> 10 | D5: =$B$5 -> 10 | E5: =$B$5 -> 10 | F5: =$B$5 -> 10 | G5: =$B$5 -> 10
A6: Потребление, стр/мес | B6: =Юнит_экономика!B9*B5 -> 5000 | C6: =Юнит_экономика!C9*C5 -> 15000 | D6: =Юнит_экономика!D9*D5 -> 7500 | E6: =Юнит_экономика!E9*E5 -> 8250 | F6: =Юнит_экономика!F9*F5 -> 30000 | G6: =Юнит_экономика!G9*G5 -> 200000
A7: ВЫРУЧКА с биллингом перерасхода, ₽ | B7: =MAX(Юнит_экономика!B7,Юнит_экономика!B4+MAX(0,B6-Юнит_экономика!B5)*Юнит_экономика!B6) -> 55900 | C7: =MAX(Юнит_экономика!C7,Юнит_экономика!C4+MAX(0,C6-Юнит_экономика!C5)*Юнит_экономика!C6) -> 127900 | D7: =MAX(Юнит_экономика!D7,Юнит_экономика!D4+MAX(0,D6-Юнит_экономика!D5)*Юнит_экономика!D6) -> 70650 | E7: =MAX(Юнит_экономика!E7,Юнит_экономика!E4+MAX(0,E6-Юнит_экономика!E5)*Юнит_экономика!E6) -> 99000 | F7: =MAX(Юнит_экономика!F7,Юнит_экономика!F4+MAX(0,F6-Юнит_экономика!F5)*Юнит_экономика!F6) -> 184000 | G7: =MAX(Юнит_экономика!G7,Юнит_экономика!G4+MAX(0,G6-Юнит_экономика!G5)*Юнит_экономика!G6) -> 689000
A8: Токены, ₽ | B8: =-B6*Допущения!$B$23 -> -155 | C8: =-C6*Допущения!$B$23 -> -465 | D8: =-D6*Допущения!$B$23 -> -232.5 | E8: =-E6*Допущения!$B$23 -> -255.75 | F8: =-F6*Допущения!$B$23 -> -930 | G8: =-G6*Допущения!$B$23 -> -6200
A9: Поддержка, ₽ | B9: =Юнит_экономика!B14 -> -6000 | C9: =Юнит_экономика!C14 -> -6000 | D9: =Юнит_экономика!D14 -> -2000 | E9: =Юнит_экономика!E14 -> -2000 | F9: =Юнит_экономика!F14 -> -6000 | G9: =Юнит_экономика!G14 -> -8000 | H9: ДОПУЩЕНИЕ: часы поддержки не растут вместе с объёмом. Спорно.
A10: Валовая маржа полная, ₽ | B10: =B7+B8+B9 -> 49745 | C10: =C7+C8+C9 -> 121435 | D10: =D7+D8+D9 -> 68417.5 | E10: =E7+E8+E9 -> 96744.25 | F10: =F7+F8+F9 -> 177070 | G10: =G7+G8+G9 -> 674800
A11: Валовая маржа полная, % | B11: =IFERROR(B10/B7,0) -> 0.88989267 | C11: =IFERROR(C10/C7,0) -> 0.9494527 | D11: =IFERROR(D10/D7,0) -> 0.96840057 | E11: =IFERROR(E10/E7,0) -> 0.97721465 | F11: =IFERROR(F10/F7,0) -> 0.96233696 | G11: =IFERROR(G10/G7,0) -> 0.97939042
A12: Эффективная цена, ₽/стр | B12: =IFERROR(B7/B6,0) -> 11.18 | C12: =IFERROR(C7/C6,0) -> 8.5266667 | D12: =IFERROR(D7/D6,0) -> 9.42 | E12: =IFERROR(E7/E6,0) -> 12 | F12: =IFERROR(F7/F6,0) -> 6.1333333 | G12: =IFERROR(G7/G6,0) -> 3.445
A13: Альтернатива клиента, ₽/мес | B13: =B6*Допущения!$B$39 -> 200000 | C13: =C6*Допущения!$B$39 -> 600000 | D13: =D6*Допущения!$B$39 -> 300000 | E13: =E6*Допущения!$B$39 -> 330000 | F13: =F6*Допущения!$B$39 -> 1200000 | G13: =G6*Допущения!$B$39 -> 8000000
A14: Во сколько раз дешевле ручного труда | B14: =IFERROR(B13/B7,0) -> 3.5778175 | C14: =IFERROR(C13/C7,0) -> 4.691165 | D14: =IFERROR(D13/D7,0) -> 4.2462845 | E14: =IFERROR(E13/E7,0) -> 3.3333333 | F14: =IFERROR(F13/F7,0) -> 6.5217391 | G14: =IFERROR(G13/G7,0) -> 11.61103
A15: Загрузка ёмкости одним таким клиентом, % | B15: =B6/Допущения!$B$55 -> 0.0069630125 | C15: =C6/Допущения!$B$55 -> 0.020889037 | D15: =D6/Допущения!$B$55 -> 0.010444519 | E15: =E6/Допущения!$B$55 -> 0.011488971 | F15: =F6/Допущения!$B$55 -> 0.041778075 | G15: =G6/Допущения!$B$55 -> 0.2785205
A17: ВЫВОД БЛОКА 1: при работающем биллинге перерасхода десятикратный объём не ухудшает маржу, а улучшает её — перерасход тарифицируется по 3–12 ₽/стр при себестоимости 0.031 ₽/стр. Риск здесь не в расходах, а в двух других местах: часы поддержки крупного клиента почти наверняка вырастут, и эффективная цена падает настолько, что клиент начинает выглядеть недоплачивающим относительно приносимой ценности.
A19: БЛОК 2. ПРИ КАКОМ ОБЪЁМЕ ТАРИФ ПЕРЕСТАЁТ БЫТЬ ВЫГОДНЫМ
A20: Показатель | B20: Т1. Пилот 19 900 ₽ / 500 стр (текущий) | C20: Т1-мод. Пилот 19 900 ₽ / 1 500 стр (та же цена, квота ×3) | D20: Т2. Подписка 9 900 ₽ / 750 стр ограниченный SLA | E20: Т3. Без подписки 12 ₽/стр, мин. чек 9 900 ₽ ограниченный SLA | F20: Бизнес 49 000 ₽ / 3 000 стр (справочно) | G20: Корпоратив 149 000 ₽ / 20 000 стр (справочно) | H20: Комментарий
A21: Объём, при котором ТОКЕНЫ съедают всю выручку (если перерасход НЕ биллится), стр | B21: =IFERROR(Юнит_экономика!B10/Допущения!$B$23,0) -> 641935.48 | C21: =IFERROR(Юнит_экономика!C10/Допущения!$B$23,0) -> 641935.48 | D21: =IFERROR(Юнит_экономика!D10/Допущения!$B$23,0) -> 319354.84 | E21: =IFERROR(Юнит_экономика!E10/Допущения!$B$23,0) -> 319354.84 | F21: =IFERROR(Юнит_экономика!F10/Допущения!$B$23,0) -> 1580645.2 | G21: =IFERROR(Юнит_экономика!G10/Допущения!$B$23,0) -> 4806451.6 | H21: Только для случая, когда квота фактически безлимитна.
A22: То же в долях от месячной ёмкости | B22: =B21/Допущения!$B$55 -> 0.89396096 | C22: =C21/Допущения!$B$55 -> 0.89396096 | D22: =D21/Допущения!$B$55 -> 0.44473435 | E22: =E21/Допущения!$B$55 -> 0.44473435 | F22: =F21/Допущения!$B$55 -> 2.2012104 | G22: =G21/Допущения!$B$55 -> 6.6934765 | H22: Значения выше 100% недостижимы физически.
A23: Объём, при котором ЭФФЕКТИВНАЯ ЦЕНА падает до 1 ₽/стр, стр | B23: =IFERROR(Юнит_экономика!B10/1,0) -> 19900 | C23: =IFERROR(Юнит_экономика!C10/1,0) -> 19900 | D23: =IFERROR(Юнит_экономика!D10/1,0) -> 9900 | E23: =IFERROR(Юнит_экономика!E10/1,0) -> 9900 | F23: =IFERROR(Юнит_экономика!F10/1,0) -> 49000 | G23: =IFERROR(Юнит_экономика!G10/1,0) -> 149000 | H23: Точка, где клиент платит символически относительно ценности.
A24: Объём безубыточности по ПОЛНЫМ расходам (с поддержкой), стр | B24: =IFERROR((Юнит_экономика!B10+Юнит_экономика!B14)/Допущения!$B$23,0) -> 448387.1 | C24: =IFERROR((Юнит_экономика!C10+Юнит_экономика!C14)/Допущения!$B$23,0) -> 448387.1 | D24: =IFERROR((Юнит_экономика!D10+Юнит_экономика!D14)/Допущения!$B$23,0) -> 254838.71 | E24: =IFERROR((Юнит_экономика!E10+Юнит_экономика!E14)/Допущения!$B$23,0) -> 254838.71 | F24: =IFERROR((Юнит_экономика!F10+Юнит_экономика!F14)/Допущения!$B$23,0) -> 1387096.8 | G24: =IFERROR((Юнит_экономика!G10+Юнит_экономика!G14)/Допущения!$B$23,0) -> 4548387.1 | H24: Объём, при котором выручка перестаёт покрывать токены + ваши часы, если перерасход не биллится.
A25: Вердикт | B25: =IF(B22>1,"Недостижимо в пределах ёмкости","Достижимо — риск реален") -> Достижимо — риск реален | C25: =IF(C22>1,"Недостижимо в пределах ёмкости","Достижимо — риск реален") -> Достижимо — риск реален | D25: =IF(D22>1,"Недостижимо в пределах ёмкости","Достижимо — риск реален") -> Достижимо — риск реален | E25: =IF(E22>1,"Недостижимо в пределах ёмкости","Достижимо — риск реален") -> Достижимо — риск реален | F25: =IF(F22>1,"Недостижимо в пределах ёмкости","Достижимо — риск реален") -> Недостижимо в пределах ёмкости | G25: =IF(G22>1,"Недостижимо в пределах ёмкости","Достижимо — риск реален") -> Недостижимо в пределах ёмкости
A27: ВЫВОД БЛОКА 2: со стороны расходов входной тариф не ломается практически никогда — токены слишком дёшевы. Единственный сценарий провала — квота, которую вы фактически не контролируете (безлимит по договору или неработающий учёт перерасхода) у клиента с объёмом в сотни тысяч страниц. Отсюда практическое требование: пока учёт расхода по клиентам не запущен, во входном тарифе должен быть жёсткий технический лимит, а не только строчка в договоре.
A29: БЛОК 3. ЛЕСТНИЦА ТАРИФОВ — ГДЕ КЛИЕНТУ ВЫГОДНО ОСТАТЬСЯ НА НИЖНЕМ ТАРИФЕ
A30: Переход | B30: Нижний тариф дешевле до объёма, стр | C30: Квота верхнего тарифа, стр | D30: Диагноз
A31: Пилот 19 900 / 500 → Бизнес 49 000 / 3 000 | B31: =Юнит_экономика!B5+(Юнит_экономика!F4-Юнит_экономика!B4)/Юнит_экономика!B6 -> 4137.5 | C31: =Юнит_экономика!F5 -> 3000 | D31: =IF(B31>C31,"РАЗРЫВ: до квоты верхнего тарифа переходить невыгодно","Лестница корректна") -> РАЗРЫВ: до квоты верхнего тарифа переходить невыгодно
A32: Бизнес 49 000 / 3 000 → Корпоратив 149 000 / 20 000 | B32: =Юнит_экономика!F5+(Юнит_экономика!G4-Юнит_экономика!F4)/Юнит_экономика!F6 -> 23000 | C32: =Юнит_экономика!G5 -> 20000 | D32: =IF(B32>C32,"РАЗРЫВ: до квоты верхнего тарифа переходить невыгодно","Лестница корректна") -> РАЗРЫВ: до квоты верхнего тарифа переходить невыгодно
A34: ВЫВОД БЛОКА 3: Пилот с перерасходом по 8 ₽/стр остаётся дешевле Бизнеса вплоть до 4 138 страниц, а квота Бизнеса — 3 000. Бизнес дешевле Корпоратива до 23 000 страниц при квоте Корпоратива 20 000. Рациональный клиент никогда не переходит на верхний тариф добровольно — он сидит на нижнем и платит перерасход. Для нас это не убыток (маржа на перерасходе выше), но выручка становится непредсказуемой, а обещанная лестница апсейла не работает. Чтобы она заработала, цена перерасхода нижнего тарифа должна быть выше, чем цена страницы внутри квоты верхнего.
A36: БЛОК 4. ЧУВСТВИТЕЛЬНОСТЬ МИНИМАЛЬНОЙ ЦЕНЫ К СТОИМОСТИ ВАШЕГО ЧАСА (вариант Б, 1 клиент, 500 стр)
A37: Стоимость часа, ₽ | B37: 1 ч поддержки | C37: 2 ч | D37: 3 ч | E37: 4 ч | F37: Комментарий
A38: 1000 | B38: =Допущения!$B$22+1*$A38+500*Допущения!$B$23 -> 9015.5 | C38: =Допущения!$B$22+2*$A38+500*Допущения!$B$23 -> 10015.5 | D38: =Допущения!$B$22+3*$A38+500*Допущения!$B$23 -> 11015.5 | E38: =Допущения!$B$22+4*$A38+500*Допущения!$B$23 -> 12015.5
A39: 1500 | B39: =Допущения!$B$22+1*$A39+500*Допущения!$B$23 -> 9515.5 | C39: =Допущения!$B$22+2*$A39+500*Допущения!$B$23 -> 11015.5 | D39: =Допущения!$B$22+3*$A39+500*Допущения!$B$23 -> 12515.5 | E39: =Допущения!$B$22+4*$A39+500*Допущения!$B$23 -> 14015.5
A40: 2000 | B40: =Допущения!$B$22+1*$A40+500*Допущения!$B$23 -> 10015.5 | C40: =Допущения!$B$22+2*$A40+500*Допущения!$B$23 -> 12015.5 | D40: =Допущения!$B$22+3*$A40+500*Допущения!$B$23 -> 14015.5 | E40: =Допущения!$B$22+4*$A40+500*Допущения!$B$23 -> 16015.5 | F40: Ваша строка: 2 000 ₽/час.
A41: 2500 | B41: =Допущения!$B$22+1*$A41+500*Допущения!$B$23 -> 10515.5 | C41: =Допущения!$B$22+2*$A41+500*Допущения!$B$23 -> 13015.5 | D41: =Допущения!$B$22+3*$A41+500*Допущения!$B$23 -> 15515.5 | E41: =Допущения!$B$22+4*$A41+500*Допущения!$B$23 -> 18015.5
A42: 3000 | B42: =Допущения!$B$22+1*$A42+500*Допущения!$B$23 -> 11015.5 | C42: =Допущения!$B$22+2*$A42+500*Допущения!$B$23 -> 14015.5 | D42: =Допущения!$B$22+3*$A42+500*Допущения!$B$23 -> 17015.5 | E42: =Допущения!$B$22+4*$A42+500*Допущения!$B$23 -> 20015.5
A44: ВЫВОД БЛОКА 4: минимальная цена почти целиком определяется стоимостью вашего часа и числом часов, а не расходами на инфраструктуру. Удвоение ставки с 1 000 до 2 000 ₽ поднимает пол входного тарифа на 3 000–6 000 ₽. Это значит, что решение о цене — на самом деле решение о том, сколько поддержки вы обещаете.
A46: БЛОК 5. МАРЖА ВХОДНОГО ТАРИФА ПРИ РАЗНОМ ЧИСЛЕ ЧАСОВ ПОДДЕРЖКИ
A47: Часов поддержки | B47: Т1. 19 900 | C47: Т1-мод. 19 900 | D47: Т2. 9 900 | E47: Т3. мин. чек 9 900 | F47: Комментарий
A48: 1 | B48: =(Юнит_экономика!B10+Юнит_экономика!B13-$A48*Допущения!$B$28)/Юнит_экономика!B10 -> 0.89871859 | C48: =(Юнит_экономика!C10+Юнит_экономика!C13-$A48*Допущения!$B$28)/Юнит_экономика!C10 -> 0.8971608 | D48: =(Юнит_экономика!D10+Юнит_экономика!D13-$A48*Допущения!$B$28)/Юнит_экономика!D10 -> 0.79563131 | E48: =(Юнит_экономика!E10+Юнит_экономика!E13-$A48*Допущения!$B$28)/Юнит_экономика!E10 -> 0.79539646
A49: 2 | B49: =(Юнит_экономика!B10+Юнит_экономика!B13-$A49*Допущения!$B$28)/Юнит_экономика!B10 -> 0.79821608 | C49: =(Юнит_экономика!C10+Юнит_экономика!C13-$A49*Допущения!$B$28)/Юнит_экономика!C10 -> 0.79665829 | D49: =(Юнит_экономика!D10+Юнит_экономика!D13-$A49*Допущения!$B$28)/Юнит_экономика!D10 -> 0.59361111 | E49: =(Юнит_экономика!E10+Юнит_экономика!E13-$A49*Допущения!$B$28)/Юнит_экономика!E10 -> 0.59337626 | F49: Отрицательное значение = клиент убыточен с учётом вашего времени.
...

Sheet Рекомендация
B1: РЕКОМЕНДАЦИЯ ПО ВХОДНОЙ ЦЕНЕ
B3: ОТВЕТ НА ГЛАВНЫЙ ВОПРОС
B4: Минимальная входная цена при варианте постоянных расходов Б и одном клиенте: 10 016 ₽/мес при 1 часе поддержки, 14 016 ₽ при 3 часах, 16 016 ₽ при 4 часах. Кассовый пол, если своё время не считать расходом, — 8 016 ₽/мес.
B5: Из этого следует вывод, обратный вашему предположению: 19 900 ₽ не является завышенной ценой по расходам. Она превышает порог окупаемости всего в 1.2–2.0 раза. Пространство для снижения существует, но оно узкое.
B6: НАСТОЯЩАЯ ПРОБЛЕМА ТАРИФА ПИЛОТ — НЕ ЦЕНА, А КВОТА
B7: 19 900 ₽ за 500 страниц даёт эффективную цену 39.8 ₽ за страницу. Альтернатива клиента — ручная вычитка за 20–60 ₽ за страницу, середина 40 ₽. То есть тариф стоит ровно столько же, сколько то, что он заменяет. Экономии нет — клиенту нечего обосновывать перед своим руководством.
B8: При этом квота — самый дешёвый параметр в модели. Увеличение квоты с 500 до 1 500 страниц стоит нам 31 ₽ токенов в месяц и превращает предложение из «столько же, сколько вручную» в «втрое дешевле, чем вручную».
B9: СРАВНЕНИЕ ТРЁХ КОНСТРУКЦИЙ ВХОДНОГО ТАРИФА
B10: 1) Подписка 19 900 ₽ / 500 страниц. Маржа 69.8% при 3 часах поддержки, безубыточность при 1 клиенте (вариант Б). Экономика лучшая из трёх. Ценность для клиента — нулевая. Продать будет трудно не из-за суммы, а из-за отсутствия выгоды.
B11: 2) Подписка 9 900 ₽ / 750 страниц с ограниченным SLA (только почта, ответ в течение рабочего дня). Эффективная цена 13.2 ₽/стр — втрое дешевле ручного труда. Валовая маржа 79.6% при 1 часе поддержки, 39.2% при 3 часах, 18.9% при 4 часах. Полная безубыточность наступает со ВТОРОГО клиента даже при идеальном SLA: вклад одного клиента при 1 часе поддержки составляет 7 877 ₽ против 8 000 ₽ постоянных расходов — не хватает 123 ₽. При 3 часах поддержки нужно 3 клиента.
B12: 3) Без подписки: 12 ₽ за страницу, минимальный месячный чек 9 900 ₽. Эффективная цена 12 ₽/стр — прямое сравнение с ручной вычиткой в одних единицах, самая понятная клиенту конструкция. Экономика на минимальном чеке совпадает с вариантом 2. Недостаток: выручка непредсказуема, и при большом объёме клиент платит меньше, чем на подписке с квотой.
B13: ЧТО РЕКОМЕНДУЕТСЯ
... B25: Рыночный спрос, конверсию, отток, стоимость привлечения клиента, налоги, разовые платежи за внедрение и разрывы в оплате. Этих данных у нас нет, и они не выдуманы. Все допущения собраны на листе «Допущения» с жёлтой заливкой.
