Workbook

Sheet Допущения_и_данные
A1: ЭКОНОМИКА СЕРВИСА АНОНИМИЗАЦИИ ПДн — ИСХОДНЫЕ ДАННЫЕ И ДОПУЩЕНИЯ
A2: Рубли, российский рынок, без НДС. Управленческий расчёт — стандарты GAAP/МСФО не применяются.
A3: СИНИЙ = ввод · ЧЁРНЫЙ = формула · ЗЕЛЁНЫЙ = ссылка на другой лист · ЖЁЛТАЯ ЗАЛИВКА = ДОПУЩЕНИЕ, которого нет в ваших данных
A5: ДАНО: ПРАЙС ПОСТАВЩИКА (Selectel), руб. за 1 млн токенов
A6: Модель | B6: Вход | C6: Выход | D6: Чтение кэша | E6: Запись кэша | F6: Скидка кэша
A7: Gemma 4 26B A4B | B7: 7.4 | C7: 40.68 | D7: 0.74 | E7: — | F7: =1-D7/B7 -> 0.9 | J7: Кэш даёт 90% скидки — это делает модель радикально дешевле при повторяющемся системном тексте.
A8: Gemma 4 31B | B8: 14.79 | C8: 43.15 | D8: 11.09 | E8: — | F8: =1-D8/B8 -> 0.25016903 | J8: ВНИМАНИЕ: у этой модели чтение кэша стоит 11.09 против входа 14.79 — скидка всего 25%. Кэширование её почти не спасает.
A9: Qwen3.5-27B | B9: 24.04 | C9: 192.31 | D9: 2.4 | E9: — | F9: =1-D9/B9 -> 0.90016639
A10: Qwen3.5-35B-A3B | B10: 17.26 | C10: 123.27 | D10: 1.73 | E10: — | F10: =1-D10/B10 -> 0.89976825
A11: Скидка чтения кэша к цене входа | J11: ДОПУЩЕНИЕ: прочерк в столбце «Запись кэша» прочитан как «запись не тарифицируется». Если поставщик имеет в виду «кэширование недоступно», расчёт с кэшем нужно выбросить целиком. Это надо уточнить у Selectel — вопрос №1.
A13: ИЗМЕРЕНО: ТРИ РЕАЛЬНЫХ ДОКУМЕНТА (подсчёт каждого токена)
A14: Документ | B14: Символов | C14: Страниц | D14: Вызовов | E14: Вход, ток. | F14: Выход, ток. | G14: Время, с | H14: Обращений к NER
A15: Договор ГПХ | B15: 2493 | C15: 1.4 | D15: 4 | E15: 9138 | F15: 1179 | G15: 35.3 | H15: 36
A16: Протокол совещания | B16: 16888 | C16: 9.4 | D16: 12 | E16: 32193 | F16: 4766 | G16: 80.7 | H16: 160
A17: Транскрипт встречи | B17: 53460 | C17: 29.7 | D17: 57 | E17: 160344 | F17: 2834 | G17: 75.9 | H17: 552
A18: ИТОГО / СРЕДНЕЕ | B18: =SUM(B15:B17) -> 72841 | C18: =SUM(C15:C17) -> 40.5 | D18: =SUM(D15:D17) -> 73 | E18: =SUM(E15:E17) -> 201675 | F18: =SUM(F15:F17) -> 8779 | G18: =SUM(G15:G17) -> 191.9 | H18: =SUM(H15:H17) -> 748
A20: Знаков в странице | B20: 1800 | I20: ДАНО
A21: Входных токенов на страницу | B21: =E18/C18 -> 4979.6296 | J21: Заявлено 4 983 — сходится.
A22: Выходных токенов на страницу | B22: =F18/C18 -> 216.76543 | J22: Заявлено 217 — сходится.
A23: Отношение вход/выход | B23: =E18/F18 -> 22.972434 | J23: Заявлено 23x — сходится. Сервис много читает и мало пишет, поэтому цена ВХОДА решает всё.
A24: Вызовов модели на страницу | B24: =D18/C18 -> 1.8024691 | J24: Заявлено 1.8 — сходится.
A25: Обращений к NER на страницу | B25: =H18/C18 -> 18.469136 | J25: Выведено из ваших данных: 748 обращений на 40.5 страницы.
A26: Средний размер документа, стр. | B26: =C18/3 -> 13.5 | I26: ДОПУЩЕНИЕ | J26: Среднее трёх измеренных. ДОПУЩЕНИЕ при переносе на другие документы.
A28: Доля входных токенов, попадающих под цену чтения кэша | B28: 0.43 | I28: ДАНО | J28: 43% входа — дословно повторяющийся системный текст. РИСК: это верхняя граница. Кэш живёт ограниченное время; если между документами клиента проходит больше времени жизни кэша, доля фактических попаданий будет ниже. Вопрос №2 к поставщику — время жизни кэша.
A29: Фактическая доля попаданий в кэш (что использовать в расчёте) | B29: =B28 -> 0.43 | I29: ДОПУЩЕНИЕ | J29: Поставьте меньше 43%, чтобы увидеть чувствительность к промахам кэша.
A31: ДАНО: АЛЬТЕРНАТИВА ПОШТУЧНОЙ ОПЛАТЕ
A32: Фиксированная плата за доступ к модели, ₽/мес | B32: 30000 | I32: ДАНО
A34: ИЗМЕРЕНО: ПРОИЗВОДИТЕЛЬНОСТЬ
A35: Время одного вызова модели, с | B35: 12.8 | I35: ДАНО | J35: ДАНО
A36: Время вызова при 32 одновременных, с | B36: 14.5 | I36: ДАНО | J36: ДАНО. Задержка почти не растёт — значит упираемся не в очередь, а в шлюз.
A37: Пропускная способность при 32 одновременных, вызовов/с | B37: 2.15 | I37: ДАНО | J37: ДАНО
A38: Потолок одновременных вызовов (выше шлюз отказывает) | B38: 32 | I38: ДАНО | J38: ДАНО
A39: Размер пачки вызовов на документ | B39: 8 | I39: ДАНО | J39: ДАНО
A40: Время обработки документа, с | B40: 78 | I40: ДОПУЩЕНИЕ | J40: ДОПУЩЕНИЕ: середина измеренного диапазона 76–81 с.
A42: ДОПУЩЕНИЯ — НИ ОДНОГО ИЗ ЭТИХ ЧИСЕЛ НЕТ В ВАШИХ ДАННЫХ
A43: Рабочих дней в месяце | B43: 22 | I43: ДОПУЩЕНИЕ | J43: Календарное допущение.
A44: Рабочих часов в дне | B44: 8 | I44: ДОПУЩЕНИЕ | J44: Определяет и профили клиентов, и месячный предел мощности.
A45: Комфортная загрузка мощности | B45: 0.7 | I45: ДОПУЩЕНИЕ | J45: Выше этой доли очередь начинает заметно расти. Инженерное правило, а не измерение.
A46: Хостинг сервиса распознавания имён (NER), ₽/мес | B46: 3000 | I46: ДОПУЩЕНИЕ | J46: НУЖНО ОТ ВАС. В прайсе поставщика его нет. 3 000 ₽ — оценка небольшой виртуальной машины. Это может оказаться и 15 000 ₽, если сервису нужен GPU. Вопрос №3.
A47: Сервер и домен веб-сервиса, ₽/мес | B47: 5000 | I47: ДОПУЩЕНИЕ | J47: НУЖНО ОТ ВАС. Перенесено из вашего предыдущего брифа.
...

Sheet Себестоимость
A1: СЕБЕСТОИМОСТЬ ТОКЕНОВ ПО ЧЕТЫРЁМ МОДЕЛЯМ
A2: Расход считается напрямую из измеренных токенов и прайса. Никаких допущений, кроме доли попаданий в кэш.
A4: БЕЗ КЭША — весь вход по полной цене
A5: Модель | B5: Договор ГПХ 1.4 стр, ₽ | C5: Протокол 9.4 стр, ₽ | D5: Транскрипт 29.7 стр, ₽ | E5: Договор ₽/стр | F5: Протокол ₽/стр | G5: Транскрипт ₽/стр | H5: СРЕДНЯЯ СТРАНИЦА, ₽
A6: Gemma 4 26B A4B | B6: =(Допущения_и_данные!$E$15*Допущения_и_данные!$B$7+Допущения_и_данные!$F$15*Допущения_и_данные!$C$7)/1000000 -> 0.11558292 | C6: =(Допущения_и_данные!$E$16*Допущения_и_данные!$B$7+Допущения_и_данные!$F$16*Допущения_и_данные!$C$7)/1000000 -> 0.43210908 | D6: =(Допущения_и_данные!$E$17*Допущения_и_данные!$B$7+Допущения_и_данные!$F$17*Допущения_и_данные!$C$7)/1000000 -> 1.3018327 | E6: =B6/Допущения_и_данные!$C$15 -> 0.082559229 | F6: =C6/Допущения_и_данные!$C$16 -> 0.045969051 | G6: =D6/Допущения_и_данные!$C$17 -> 0.043832752 | H6: =((Допущения_и_данные!$E$18/Допущения_и_данные!$C$18)*Допущения_и_данные!$B$7+(Допущения_и_данные!$F$18/Допущения_и_данные!$C$18)*Допущения_и_данные!$C$7)/1000000 -> 0.045667277
A7: Gemma 4 31B | B7: =(Допущения_и_данные!$E$15*Допущения_и_данные!$B$8+Допущения_и_данные!$F$15*Допущения_и_данные!$C$8)/1000000 -> 0.18602487 | C7: =(Допущения_и_данные!$E$16*Допущения_и_данные!$B$8+Допущения_и_данные!$F$16*Допущения_и_данные!$C$8)/1000000 -> 0.68178737 | D7: =(Допущения_и_данные!$E$17*Допущения_и_данные!$B$8+Допущения_и_данные!$F$17*Допущения_и_данные!$C$8)/1000000 -> 2.4937749 | E7: =B7/Допущения_и_данные!$C$15 -> 0.13287491 | F7: =C7/Допущения_и_данные!$C$16 -> 0.072530571 | G7: =D7/Допущения_и_данные!$C$17 -> 0.083965484 | H7: =((Допущения_и_данные!$E$18/Допущения_и_данные!$C$18)*Допущения_и_данные!$B$8+(Допущения_и_данные!$F$18/Допущения_и_данные!$C$18)*Допущения_и_данные!$C$8)/1000000 -> 0.083002151
A8: Qwen3.5-27B | B8: =(Допущения_и_данные!$E$15*Допущения_и_данные!$B$9+Допущения_и_данные!$F$15*Допущения_и_данные!$C$9)/1000000 -> 0.44641101 | C8: =(Допущения_и_данные!$E$16*Допущения_и_данные!$B$9+Допущения_и_данные!$F$16*Допущения_и_данные!$C$9)/1000000 -> 1.6904692 | D8: =(Допущения_и_данные!$E$17*Допущения_и_данные!$B$9+Допущения_и_данные!$F$17*Допущения_и_данные!$C$9)/1000000 -> 4.3996763 | E8: =B8/Допущения_и_данные!$C$15 -> 0.31886501 | F8: =C8/Допущения_и_данные!$C$16 -> 0.17983715 | G8: =D8/Допущения_и_данные!$C$17 -> 0.14813725 | H8: =((Допущения_и_данные!$E$18/Допущения_и_данные!$C$18)*Допущения_и_данные!$B$9+(Допущения_и_данные!$F$18/Допущения_и_данные!$C$18)*Допущения_и_данные!$C$9)/1000000 -> 0.16139646
A9: Qwen3.5-35B-A3B | B9: =(Допущения_и_данные!$E$15*Допущения_и_данные!$B$10+Допущения_и_данные!$F$15*Допущения_и_данные!$C$10)/1000000 -> 0.30305721 | C9: =(Допущения_и_данные!$E$16*Допущения_и_данные!$B$10+Допущения_и_данные!$F$16*Допущения_и_данные!$C$10)/1000000 -> 1.143156 | D9: =(Допущения_и_данные!$E$17*Допущения_и_данные!$B$10+Допущения_и_данные!$F$17*Допущения_и_данные!$C$10)/1000000 -> 3.1168846 | E9: =B9/Допущения_и_данные!$C$15 -> 0.21646944 | F9: =C9/Допущения_и_данные!$C$16 -> 0.12161234 | G9: =D9/Допущения_и_данные!$C$17 -> 0.10494561 | H9: =((Допущения_и_данные!$E$18/Допущения_и_данные!$C$18)*Допущения_и_данные!$B$10+(Допущения_и_данные!$F$18/Допущения_и_данные!$C$18)*Допущения_и_данные!$C$10)/1000000 -> 0.11266908
A13: С КЭШЕМ — 43% входа по цене чтения кэша
A14: Модель | B14: Договор ГПХ 1.4 стр, ₽ | C14: Протокол 9.4 стр, ₽ | D14: Транскрипт 29.7 стр, ₽ | E14: Договор ₽/стр | F14: Протокол ₽/стр | G14: Транскрипт ₽/стр | H14: СРЕДНЯЯ СТРАНИЦА, ₽
A15: Gemma 4 26B A4B | B15: =(Допущения_и_данные!$E$15*(1-Допущения_и_данные!$B$29)*Допущения_и_данные!$B$7+Допущения_и_данные!$E$15*Допущения_и_данные!$B$29*Допущения_и_данные!$D$7+Допущения_и_данные!$F$15*Допущения_и_данные!$C$7)/1000000 -> 0.089413516 | C15: =(Допущения_и_данные!$E$16*(1-Допущения_и_данные!$B$29)*Допущения_и_данные!$B$7+Допущения_и_данные!$E$16*Допущения_и_данные!$B$29*Допущения_и_данные!$D$7+Допущения_и_данные!$F$16*Допущения_и_данные!$C$7)/1000000 -> 0.33991477 | D15: =(Допущения_и_данные!$E$17*(1-Допущения_и_данные!$B$29)*Допущения_и_данные!$B$7+Допущения_и_данные!$E$17*Допущения_и_данные!$B$29*Допущения_и_данные!$D$7+Допущения_и_данные!$F$17*Допущения_и_данные!$C$7)/1000000 -> 0.84263957 | E15: =B15/Допущения_и_данные!$C$15 -> 0.063866797 | F15: =C15/Допущения_и_данные!$C$16 -> 0.036161145 | G15: =D15/Допущения_и_данные!$C$17 -> 0.028371703 | H15: =((Допущения_и_данные!$E$18/Допущения_и_данные!$C$18)*(1-Допущения_и_данные!$B$29)*Допущения_и_данные!$B$7+(Допущения_и_данные!$E$18/Допущения_и_данные!$C$18)*Допущения_и_данные!$B$29*Допущения_и_данные!$D$7+(Допущения_и_данные!$F$18/Допущения_и_данные!$C$18)*Допущения_и_данные!$C$7)/1000000 -> 0.031406614
A16: Gemma 4 31B | B16: =(Допущения_и_данные!$E$15*(1-Допущения_и_данные!$B$29)*Допущения_и_данные!$B$8+Допущения_и_данные!$E$15*Допущения_и_данные!$B$29*Допущения_и_данные!$D$8+Допущения_и_данные!$F$15*Допущения_и_данные!$C$8)/1000000 -> 0.17148631 | C16: =(Допущения_и_данные!$E$16*(1-Допущения_и_данные!$B$29)*Допущения_и_данные!$B$8+Допущения_и_данные!$E$16*Допущения_и_данные!$B$29*Допущения_и_данные!$D$8+Допущения_и_данные!$F$16*Допущения_и_данные!$C$8)/1000000 -> 0.63056831 | D16: =(Допущения_и_данные!$E$17*(1-Допущения_и_данные!$B$29)*Допущения_и_данные!$B$8+Допущения_и_данные!$E$17*Допущения_и_данные!$B$29*Допущения_и_данные!$D$8+Допущения_и_данные!$F$17*Допущения_и_данные!$C$8)/1000000 -> 2.2386676 | E16: =B16/Допущения_и_данные!$C$15 -> 0.12249022 | F16: =C16/Допущения_и_данные!$C$16 -> 0.067081735 | G16: =D16/Допущения_и_данные!$C$17 -> 0.075376012 | H16: =((Допущения_и_данные!$E$18/Допущения_и_данные!$C$18)*(1-Допущения_и_данные!$B$29)*Допущения_и_данные!$B$8+(Допущения_и_данные!$E$18/Допущения_и_данные!$C$18)*Допущения_и_данные!$B$29*Допущения_и_данные!$D$8+(Допущения_и_данные!$F$18/Допущения_и_данные!$C$18)*Допущения_и_данные!$C$8)/1000000 -> 0.07507956
A17: Qwen3.5-27B | B17: =(Допущения_и_данные!$E$15*(1-Допущения_и_данные!$B$29)*Допущения_и_данные!$B$9+Допущения_и_данные!$E$15*Допущения_и_данные!$B$29*Допущения_и_данные!$D$9+Допущения_и_данные!$F$15*Допущения_и_данные!$C$9)/1000000 -> 0.36138009 | C17: =(Допущения_и_данные!$E$16*(1-Допущения_и_данные!$B$29)*Допущения_и_данные!$B$9+Допущения_и_данные!$E$16*Допущения_и_данные!$B$29*Допущения_и_данные!$D$9+Допущения_и_данные!$F$16*Допущения_и_данные!$C$9)/1000000 -> 1.3909069 | D17: =(Допущения_и_данные!$E$17*(1-Допущения_и_данные!$B$29)*Допущения_и_данные!$B$9+Допущения_и_данные!$E$17*Допущения_и_данные!$B$29*Допущения_и_данные!$D$9+Допущения_и_данные!$F$17*Допущения_и_данные!$C$9)/1000000 -> 2.9076433 | E17: =B17/Допущения_и_данные!$C$15 -> 0.25812864 | F17: =C17/Допущения_и_данные!$C$16 -> 0.14796882 | G17: =D17/Допущения_и_данные!$C$17 -> 0.097900448 | H17: =((Допущения_и_данные!$E$18/Допущения_и_данные!$C$18)*(1-Допущения_и_данные!$B$29)*Допущения_и_данные!$B$9+(Допущения_и_данные!$E$18/Допущения_и_данные!$C$18)*Допущения_и_данные!$B$29*Допущения_и_данные!$D$9+(Допущения_и_данные!$F$18/Допущения_и_данные!$C$18)*Допущения_и_данные!$C$9)/1000000 -> 0.11506001
A18: Qwen3.5-35B-A3B | B18: =(Допущения_и_данные!$E$15*(1-Допущения_и_данные!$B$29)*Допущения_и_данные!$B$10+Допущения_и_данные!$E$15*Допущения_и_данные!$B$29*Допущения_и_данные!$D$10+Допущения_и_данные!$F$15*Допущения_и_данные!$C$10)/1000000 -> 0.24203456 | C18: =(Допущения_и_данные!$E$16*(1-Допущения_и_данные!$B$29)*Допущения_и_данные!$B$10+Допущения_и_данные!$E$16*Допущения_и_данные!$B$29*Допущения_и_данные!$D$10+Допущения_и_данные!$F$16*Допущения_и_данные!$C$10)/1000000 -> 0.92817437 | D18: =(Допущения_и_данные!$E$17*(1-Допущения_и_данные!$B$29)*Допущения_и_данные!$B$10+Допущения_и_данные!$E$17*Допущения_и_данные!$B$29*Допущения_и_данные!$D$10+Допущения_и_данные!$F$17*Допущения_и_данные!$C$10)/1000000 -> 2.0461234 | E18: =B18/Допущения_и_данные!$C$15 -> 0.17288183 | F18: =C18/Допущения_и_данные!$C$16 -> 0.098741954 | G18: =D18/Допущения_и_данные!$C$17 -> 0.068893045 | H18: =((Допущения_и_данные!$E$18/Допущения_и_данные!$C$18)*(1-Допущения_и_данные!$B$29)*Допущения_и_данные!$B$10+(Допущения_и_данные!$E$18/Допущения_и_данные!$C$18)*Допущения_и_данные!$B$29*Допущения_и_данные!$D$10+(Допущения_и_данные!$F$18/Допущения_и_данные!$C$18)*Допущения_и_данные!$C$10)/1000000 -> 0.079415614
A22: ЧТО ДАЁТ КЭШИРОВАНИЕ
A23: Модель | B23: ₽/стр без кэша | C23: ₽/стр с кэшем | D23: Экономия, ₽ | E23: Экономия, % | F23: Доля входа в расходе | G23: Место по цене
A24: Gemma 4 26B A4B | B24: =H6 -> 0.045667277 | C24: =H15 -> 0.031406614 | D24: =B24-C24 -> 0.014260663 | E24: =1-C24/B24 -> 0.31227313 | F24: =(Допущения_и_данные!$E$18/Допущения_и_данные!$C$18)*Допущения_и_данные!$B$7/1000000/B24 -> 0.8069073 | G24: =RANK(C24,$C$24:$C$27,1) -> 1
A25: Gemma 4 31B | B25: =H7 -> 0.083002151 | C25: =H16 -> 0.07507956 | D25: =B25-C25 -> 0.0079225907 | E25: =1-C25/B25 -> 0.095450427 | F25: =(Допущения_и_данные!$E$18/Допущения_и_данные!$C$18)*Допущения_и_данные!$B$8/1000000/B25 -> 0.88731101 | G25: =RANK(C25,$C$24:$C$27,1) -> 2
A26: Qwen3.5-27B | B26: =H8 -> 0.16139646 | C26: =H17 -> 0.11506001 | D26: =B26-C26 -> 0.04633645 | E26: =1-C26/B26 -> 0.28709707 | F26: =(Допущения_и_данные!$E$18/Допущения_и_данные!$C$18)*Допущения_и_данные!$B$9/1000000/B26 -> 0.74171577 | G26: =RANK(C26,$C$24:$C$27,1) -> 4
A27: Qwen3.5-35B-A3B | B27: =H9 -> 0.11266908 | C27: =H18 -> 0.079415614 | D27: =B27-C27 -> 0.033253469 | E27: =1-C27/B27 -> 0.2951428 | F27: =(Допущения_и_данные!$E$18/Допущения_и_данные!$C$18)*Допущения_и_данные!$B$10/1000000/B27 -> 0.76283933 | G27: =RANK(C27,$C$24:$C$27,1) -> 3
A29: САМАЯ ДЕШЁВАЯ КОМБИНАЦИЯ, ₽/стр | B29: =MIN(H15:H18) -> 0.031406614
A30: САМАЯ ДОРОГАЯ КОМБИНАЦИЯ, ₽/стр | B30: =MAX(H6:H9) -> 0.16139646
A31: Разброс между ними | B31: =B30/B29 -> 5.1389321
A33: Вход даёт 74–89% всего расхода. Это прямое следствие измеренного соотношения 23:1 — сервис читает много, пишет мало. Значит при выборе модели смотреть надо на цену входа и цену чтения кэша, а не на цену выхода.
A34: Кэширование даёт 31% экономии на Gemma 26B и всего 9.5% на Gemma 31B. Причина в прайсе: у 26B чтение кэша стоит 0.74 против входа 7.40 — скидка 90%. У 31B чтение кэша 11.09 против входа 14.79 — скидка 25%. Кэш выгоден не всегда, а только там, где поставщик даёт по нему настоящую скидку.
A35: Короткий документ дороже в пересчёте на страницу — это подтверждается: 6 527 входных токенов на страницу против 3 425 у протокола. Но зависимость немонотонная: транскрипт снова дороже протокола (5 399 токенов на страницу). Три точки не ложатся на прямую, и по ним нельзя достоверно выделить постоянную надбавку на документ. Для тарификации это не важно — расход на страницу в любом случае составляет копейки.
A36: Сверка с вашим предыдущим брифом: названные там 0.083 ₽/стр — это в точности Gemma 4 31B без кэша (0.0831), а 0.031 ₽/стр — Gemma 4 26B A4B с кэшем (0.0314). Расходы по трём документам 0.19 / 0.68 / 2.49 ₽ тоже совпадают с Gemma 4 31B без кэша. Две независимые выгрузки сошлись — данным можно доверять.

Sheet Порог_30000
A1: ПРИ КАКОМ ОБЪЁМЕ ФИКСИРОВАННЫЕ 30 000 ₽ СТАНОВЯТСЯ ДЕШЕВЛЕ ПОШТУЧНОЙ ОПЛАТЫ
A2: Сравнивается только плата за модель. NER-хостинг и сервер нужны в обоих вариантах и на порог не влияют.
A4: Модель и режим | B4: ₽/страница | C4: Порог, стр/мес | D4: Порог, стр/раб. день | E4: Порог в % от месячной мощности | F4: Порог в клиентах по 100 стр/день
A5: Gemma 26B + кэш — САМАЯ ДЕШЁВАЯ | B5: =Себестоимость!H15 -> 0.031406614 | C5: =Допущения_и_данные!$B$32/B5 -> 955212.82 | D5: =C5/Допущения_и_данные!$B$43 -> 43418.764 | E5: =C5/Мощность!$B$14 -> 1.2639048 | F5: =C5/(100*Допущения_и_данные!$B$43) -> 434.18764 | G5: Порог 955 тыс. страниц в месяц — это больше месячной мощности сервиса при 8-часовом дне. То есть на самой дешёвой модели фиксированная плата не окупится НИКОГДА: раньше кончится железо.
A6: Gemma 26B без кэша | B6: =Себестоимость!H6 -> 0.045667277 | C6: =Допущения_и_данные!$B$32/B6 -> 656925.53 | D6: =C6/Допущения_и_данные!$B$43 -> 29860.251 | E6: =C6/Мощность!$B$14 -> 0.86922127 | F6: =C6/(100*Допущения_и_данные!$B$43) -> 298.60251
A7: Gemma 31B + кэш | B7: =Себестоимость!H16 -> 0.07507956 | C7: =Допущения_и_данные!$B$32/B7 -> 399576.13 | D7: =C7/Допущения_и_данные!$B$43 -> 18162.551 | E7: =C7/Мощность!$B$14 -> 0.5287054 | F7: =C7/(100*Допущения_и_данные!$B$43) -> 181.62551
A8: Gemma 31B без кэша | B8: =Себестоимость!H7 -> 0.083002151 | C8: =Допущения_и_данные!$B$32/B8 -> 361436.42 | D8: =C8/Допущения_и_данные!$B$43 -> 16428.928 | E8: =C8/Мощность!$B$14 -> 0.47824024 | F8: =C8/(100*Допущения_и_данные!$B$43) -> 164.28928
A9: Qwen35B-A3B + кэш | B9: =Себестоимость!H18 -> 0.079415614 | C9: =Допущения_и_данные!$B$32/B9 -> 377759.47 | D9: =C9/Допущения_и_данные!$B$43 -> 17170.885 | E9: =C9/Мощность!$B$14 -> 0.49983834 | F9: =C9/(100*Допущения_и_данные!$B$43) -> 171.70885
A10: Qwen35B-A3B без кэша | B10: =Себестоимость!H9 -> 0.11266908 | C10: =Допущения_и_данные!$B$32/B10 -> 266266.48 | D10: =C10/Допущения_и_данные!$B$43 -> 12103.022 | E10: =C10/Мощность!$B$14 -> 0.35231465 | F10: =C10/(100*Допущения_и_данные!$B$43) -> 121.03022
A11: Qwen 27B + кэш | B11: =Себестоимость!H17 -> 0.11506001 | C11: =Допущения_и_данные!$B$32/B11 -> 260733.51 | D11: =C11/Допущения_и_данные!$B$43 -> 11851.523 | E11: =C11/Мощность!$B$14 -> 0.34499362 | F11: =C11/(100*Допущения_и_данные!$B$43) -> 118.51523
A12: Qwen 27B без кэша — САМАЯ ДОРОГАЯ | B12: =Себестоимость!H8 -> 0.16139646 | C12: =Допущения_и_данные!$B$32/B12 -> 185877.69 | D12: =C12/Допущения_и_данные!$B$43 -> 8448.9858 | E12: =C12/Мощность!$B$14 -> 0.24594696 | F12: =C12/(100*Допущения_и_данные!$B$43) -> 84.489858 | G12: Даже на самой дорогой модели порог — 186 тыс. страниц в месяц, это 8 444 страницы в рабочий день, или 84 клиента, каждый из которых обрабатывает 100 страниц в день.
A15: ВЫВОД: фиксированная плата 30 000 ₽ невыгодна ни при одном реалистичном объёме. Диапазон порога — от 186 тыс. до 955 тыс. страниц в месяц в зависимости от модели и кэша. Нижняя граница этого диапазона требует 84 клиентов среднего размера; верхняя физически недостижима на текущем железе.
A16: Переход на поштучную оплату экономит 30 000 ₽ в месяц минус фактический расход на токены. При реалистичных объёмах первых клиентов (единицы тысяч страниц в месяц) расход на токены — десятки рублей, то есть экономия составляет практически все 30 000 ₽.
A17: ОГОВОРКА: расчёт сравнивает только цену. Фиксированная плата может давать гарантированную мощность или приоритет в очереди — в предоставленном прайсе об этом ничего нет. Если такая гарантия есть, её стоит оценить отдельно.

Sheet Профили
A1: ПРОФИЛИ КЛИЕНТОВ: 5, 100 И 1000 СТРАНИЦ В ДЕНЬ НА СОТРУДНИКА
A2: Расчёт на одного работающего сотрудника. Разброс между профилями — 200-кратный.
A4: Показатель | B4: Лёгкий 5 стр/день | C4: Средний 100 стр/день | D4: Тяжёлый 1000 стр/день | E4: Разброс
A5: Страниц в день (ввод) | B5: 5 | C5: 100 | D5: 1000 | E5: =D5/B5 -> 200
A6: Страниц в месяц | B6: =B5*Допущения_и_данные!$B$43 -> 110 | C6: =C5*Допущения_и_данные!$B$43 -> 2200 | D6: =D5*Допущения_и_данные!$B$43 -> 22000 | E6: =IFERROR(D6/B6,0) -> 200
A7: Страниц в час работы | B7: =B5/Допущения_и_данные!$B$44 -> 0.625 | C7: =C5/Допущения_и_данные!$B$44 -> 12.5 | D7: =D5/Допущения_и_данные!$B$44 -> 125 | E7: =IFERROR(D7/B7,0) -> 200
A8: Документов в месяц (средний размер) | B8: =B6/Допущения_и_данные!$B$26 -> 8.1481481 | C8: =C6/Допущения_и_данные!$B$26 -> 162.96296 | D8: =D6/Допущения_и_данные!$B$26 -> 1629.6296 | E8: =IFERROR(D8/B8,0) -> 200 | F8: Зависит от допущения о среднем размере документа.
A9: Вызовов модели в месяц | B9: =B6*Допущения_и_данные!$B$24 -> 198.2716 | C9: =C6*Допущения_и_данные!$B$24 -> 3965.4321 | D9: =D6*Допущения_и_данные!$B$24 -> 39654.321 | E9: =IFERROR(D9/B9,0) -> 200
A10: Обращений к NER в месяц | B10: =B6*Допущения_и_данные!$B$25 -> 2031.6049 | C10: =C6*Допущения_и_данные!$B$25 -> 40632.099 | D10: =D6*Допущения_и_данные!$B$25 -> 406320.99 | E10: =IFERROR(D10/B10,0) -> 200 | F10: 18.5 обращения на страницу — нагрузка на отдельный сервис, оплачивается хостингом.
A11: ТОКЕНЫ на самой дешёвой модели, ₽/мес | B11: =B6*Себестоимость!$B$29 -> 3.4547275 | C11: =C6*Себестоимость!$B$29 -> 69.09455 | D11: =D6*Себестоимость!$B$29 -> 690.9455 | E11: =IFERROR(D11/B11,0) -> 200 | F11: Gemma 26B с кэшем.
A12: ТОКЕНЫ на самой дорогой модели, ₽/мес | B12: =B6*Себестоимость!$B$30 -> 17.75361 | C12: =C6*Себестоимость!$B$30 -> 355.0722 | D12: =D6*Себестоимость!$B$30 -> 3550.722 | E12: =IFERROR(D12/B12,0) -> 200 | F12: Qwen 27B без кэша.
A13: Разница между моделями, ₽/мес | B13: =B12-B11 -> 14.298883 | C13: =C12-C11 -> 285.97765 | D13: =D12-D11 -> 2859.7765 | E13: =IFERROR(D13/B13,0) -> 200 | F13: Выбор модели меняет расход в 5.1 раза — но в абсолютных рублях это копейки против поддержки.
A14: Доля месячной мощности сервиса | B14: =B6/Мощность!$B$14 -> 0.00014554822 | C14: =C6/Мощность!$B$14 -> 0.0029109644 | D14: =D6/Мощность!$B$14 -> 0.029109644 | E14: =IFERROR(D14/B14,0) -> 200
A15: Сколько таких сотрудников выдержит мощность | B15: =Мощность!$B$14/B6 -> 6870.5753 | C15: =Мощность!$B$14/C6 -> 343.52877 | D15: =Мощность!$B$14/D6 -> 34.352877 | E15: =IFERROR(D15/B15,0) -> 0.005 | F15: По страницам, без учёта очереди.
A16: Альтернатива клиента — ручная вычитка, ₽/мес | B16: =B6*Допущения_и_данные!$B$57 -> 4400 | C16: =C6*Допущения_и_данные!$B$57 -> 88000 | D16: =D6*Допущения_и_данные!$B$57 -> 880000 | E16: =IFERROR(D16/B16,0) -> 200 | F16: Из предыдущего брифа: 20–60 ₽/стр, середина 40.
A17: Расход на токены в % от альтернативы | B17: =B12/B16 -> 0.0040349114 | C17: =C12/C16 -> 0.0040349114 | D17: =D12/D16 -> 0.0040349114 | E17: =IFERROR(D17/B17,0) -> 1 | F17: Даже на самой дорогой модели — сотые доли процента.
A20: ЧТО ЗДЕСЬ ВИДНО. Потребление меняется в 200 раз, расход на токены — тоже в 200 раз. Но в абсолютных величинах весь диапазон укладывается от 3 до 3 554 ₽ в месяц. Даже самый тяжёлый сотрудник на самой дорогой модели обходится в 3 554 ₽ токенов — меньше, чем 2 часа вашей поддержки.
A21: СЛЕДСТВИЕ ДЛЯ ТАРИФА: 200-кратный разброс потребления почти не влияет на наши расходы, зато полностью определяет ценность для клиента (от 4 400 до 880 000 ₽ сэкономленного ручного труда в месяц). Значит цена должна следовать за объёмом не потому, что объём нам дорого обходится, а потому, что объём — это мера полученной клиентом пользы.
A22: ВАЖНАЯ ОГОВОРКА: лёгкий профиль (5 стр/день = 110 стр/мес) экономит клиенту всего 4 400 ₽ в месяц. Это меньше, чем стоит один наш клиент в поддержке (6 000 ₽). Такому клиенту нельзя продать ничего, что окупало бы нас: порог жизнеспособности — примерно 350 стр/мес при одном клиенте и 170 стр/мес при десяти. См. лист «Тарифы».

Sheet Мощность
A1: МОЩНОСТЬ: ВЫЗОВЫ, ДОКУМЕНТЫ И ЛЮДИ — ЭТО ТРИ РАЗНЫЕ ВЕЛИЧИНЫ
A3: УРОВЕНЬ 1. ОДНОВРЕМЕННЫЕ ОБРАЩЕНИЯ К МОДЕЛИ — то, во что упирается шлюз
A4: Потолок одновременных вызовов | B4: =Допущения_и_данные!$B$38 -> 32 | F4: Выше этого шлюз начинает отказывать.
A5: Пропускная способность, вызовов/с | B5: =Допущения_и_данные!$B$37 -> 2.15 | F5: Измерено при 32 одновременных.
A6: Вызовов модели на страницу | B6: =Допущения_и_данные!$B$24 -> 1.8024691 | F6: Выведено из ваших трёх документов.
A7: СТРАНИЦ В ЧАС — жёсткий потолок | B7: =Допущения_и_данные!$B$37*3600/Допущения_и_данные!$B$24 -> 4294.1096 | F7: Главное число всей мощности.
A8: Страниц в час при комфортной загрузке | B8: =B7*Допущения_и_данные!$B$45 -> 3005.8767 | F8: ДОПУЩЕНИЕ: 70%. Выше очередь растёт нелинейно.
A10: УРОВЕНЬ 2. ДОКУМЕНТЫ В ОБРАБОТКЕ — то, что определяет время ожидания
A11: Размер пачки вызовов на документ | B11: =Допущения_и_данные!$B$39 -> 8 | F11: Дано.
A12: ДОКУМЕНТОВ ОДНОВРЕМЕННО В ОБРАБОТКЕ | B12: =Допущения_и_данные!$B$38/Допущения_и_данные!$B$39 -> 4 | F12: 32 вызова / пачка по 8 = 4 документа. Пятый ждёт.
A13: Время обработки документа, с | B13: =Допущения_и_данные!$B$40 -> 78 | F13: 76–81 с почти независимо от объёма.
A14: МЕСЯЧНЫЙ ПРЕДЕЛ, страниц | B14: =B7*Допущения_и_данные!$B$44*Допущения_и_данные!$B$43 -> 755763.29 | F14: При 8-часовом дне и 22 рабочих днях.
A15: Месячный предел при комфортной загрузке, страниц | B15: =B14*Допущения_и_данные!$B$45 -> 529034.3 | F15: Рабочий ориентир для планирования.
A16: Месячный предел при круглосуточной работе, страниц | B16: =B7*730 -> 3134700 | F16: Технический максимум, если сервис работает без выходных.
A18: Документов в час по размеру документа
A19: Размер документа, стр | B19: По пропускной способности | C19: По одновременности | D19: ПРЕДЕЛ, док/час | E19: Что ограничивает
A20: Договор 1.4 стр | B20: =$B$7/Допущения_и_данные!$C$15 -> 3067.2211 | C20: =$B$12/Допущения_и_данные!$G$15*3600 -> 407.93201 | D20: =MIN(B20,C20) -> 407.93201 | E20: =IF(B20<C20,"пропускная способность","одновременность") -> одновременность | F20: У коротких документов упираемся в число одновременных документов, у длинных — в пропускную способность. Это разные узкие места, и расширяются они по-разному.
A21: Протокол 9.4 стр | B21: =$B$7/Допущения_и_данные!$C$16 -> 456.82017 | C21: =$B$12/Допущения_и_данные!$G$16*3600 -> 178.43866 | D21: =MIN(B21,C21) -> 178.43866 | E21: =IF(B21<C21,"пропускная способность","одновременность") -> одновременность
A22: Транскрипт 29.7 стр | B22: =$B$7/Допущения_и_данные!$C$17 -> 144.58281 | C22: =$B$12/Допущения_и_данные!$G$17*3600 -> 189.72332 | D22: =MIN(B22,C22) -> 144.58281 | E22: =IF(B22<C22,"пропускная способность","одновременность") -> пропускная способность
A23: Средний 13.5 стр | B23: =$B$7/Допущения_и_данные!$B$26 -> 318.08219 | C23: =$B$12/Допущения_и_данные!$B$40*3600 -> 184.61538 | D23: =MIN(B23,C23) -> 184.61538 | E23: =IF(B23<C23,"пропускная способность","одновременность") -> одновременность
A25: УРОВЕНЬ 3. ЛЮДЕЙ ЗА РАБОТОЙ — то, что видит заказчик
A26: Профиль сотрудника | B26: Страниц в час | C26: Людей при 100% загрузки | D26: Людей при комфортной загрузке
A27: 5 страниц в день | B27: =5/Допущения_и_данные!$B$44 -> 0.625 | C27: =$B$7/B27 -> 6870.5753 | D27: =$B$8/B27 -> 4809.4027
A28: 100 страниц в день | B28: =100/Допущения_и_данные!$B$44 -> 12.5 | C28: =$B$7/B28 -> 343.52877 | D28: =$B$8/B28 -> 240.47014
A29: 1000 страниц в день | B29: =1000/Допущения_и_данные!$B$44 -> 125 | C29: =$B$7/B29 -> 34.352877 | D29: =$B$8/B29 -> 24.047014
A31: Людей, если каждый непрерывно шлёт документы с паузой
A32: Пауза между документами, мин | B32: Людей за работой
A33: 2 | B33: =$B$12*(Допущения_и_данные!$B$40+A33*60)/Допущения_и_данные!$B$40 -> 10.153846 | F33: Этот расчёт объясняет число «20–34 активных пользователя» из вашего предыдущего брифа: оно соответствует паузе 5–10 минут между документами, то есть очень плотной работе. При паузе 30 минут тот же сервис обслуживает почти 100 человек.
A34: 5 | B34: =$B$12*(Допущения_и_данные!$B$40+A34*60)/Допущения_и_данные!$B$40 -> 19.384615
A35: 10 | B35: =$B$12*(Допущения_и_данные!$B$40+A35*60)/Допущения_и_данные!$B$40 -> 34.769231
A36: 30 | B36: =$B$12*(Допущения_и_данные!$B$40+A36*60)/Допущения_и_данные!$B$40 -> 96.307692
A38: КОГДА РАСШИРЯТЬ И ЧТО ИМЕННО
A39: Профиль клиента | B39: Страниц в месяц на клиента | C39: Клиентов до комфортного предела | D39: Клиентов до жёсткого предела
A40: 1 сотрудник, 5 стр/день | B40: =5*Допущения_и_данные!$B$43 -> 110 | C40: =$B$15/B40 -> 4809.4027 | D40: =$B$14/B40 -> 6870.5753
A41: 1 сотрудник, 20 стр/день | B41: =20*Допущения_и_данные!$B$43 -> 440 | C41: =$B$15/B41 -> 1202.3507 | D41: =$B$14/B41 -> 1717.6438
A42: 1 сотрудник, 100 стр/день | B42: =100*Допущения_и_данные!$B$43 -> 2200 | C42: =$B$15/B42 -> 240.47014 | D42: =$B$14/B42 -> 343.52877
A43: 1 сотрудник, 300 стр/день | B43: =300*Допущения_и_данные!$B$43 -> 6600 | C43: =$B$15/B43 -> 80.156712 | D43: =$B$14/B43 -> 114.50959
A44: 1 сотрудник, 1000 стр/день | B44: =1000*Допущения_и_данные!$B$43 -> 22000 | C44: =$B$15/B44 -> 24.047014 | D44: =$B$14/B44 -> 34.352877
A46: ЧТО РАСШИРЯТЬ В ПЕРВУЮ ОЧЕРЕДЬ. Упираемся мы не в модель и не в деньги, а в шлюз: выше 32 одновременных вызовов он отказывает. При этом задержка одного вызова почти не растёт с параллельностью (12.8 с против 14.5 с при 32 одновременных) — это признак того, что сама модель ещё не загружена, а ограничение искусственное.
A47: Порядок расширения: 1) поднять потолок одновременных вызовов в шлюзе — это самая дешёвая мера и, судя по поведению задержки, даст рост почти линейно; 2) увеличить размер пачки или число документов в параллельной обработке — снимет ограничение на коротких документах; 3) только потом добавлять мощность модели.
...

Sheet Тарифы
A1: ЧЕТЫРЕ КОНСТРУКЦИИ ТАРИФА И ИХ ЮНИТ-ЭКОНОМИКА
A2: Задача: тариф не должен требовать от нас знания среднего клиента, потому что статистики нет.
A4: ПАРАМЕТРЫ КОНСТРУКЦИЙ — все цифры предложены расчётом, меняйте свободно
A5: K1. Платформа, ₽/мес (квоты нет) | B5: 6900 | E5: ДОПУЩЕНИЕ | G5: Все цены ниже выведены из расходов и из альтернативы клиента (20–60 ₽/стр ручной вычитки, число из предыдущего брифа). Рыночных данных и цен конкурентов у нас нет, поэтому это не «рыночные» цены, а «непротиворечивые расходам» цены.
A6: K1. Цена страницы с первой, ₽/стр | B6: 8 | E6: ДОПУЩЕНИЕ
A7: K2. Подписка, ₽/мес | B7: 19900 | E7: ДОПУЩЕНИЕ
A8: K2. Включённая квота, стр | B8: 1500 | E8: ДОПУЩЕНИЕ
A9: K2. Цена сверх квоты, ₽/стр | B9: 8 | E9: ДОПУЩЕНИЕ
A10: K3. Минимальный месячный чек, ₽ | B10: 9900 | E10: ДОПУЩЕНИЕ
A11: K3. Включено в минимальный чек, стр | B11: 500 | E11: ДОПУЩЕНИЕ
A12: K3. Ступень 1: до 3 000 стр, ₽/стр | B12: 8 | E12: ДОПУЩЕНИЕ
A13: K3. Ступень 2: до 10 000 стр, ₽/стр | B13: 6 | E13: ДОПУЩЕНИЕ
A14: K3. Ступень 3: до 30 000 стр, ₽/стр | B14: 4 | E14: ДОПУЩЕНИЕ
A15: K3. Ступень 4: свыше 30 000 стр, ₽/стр | B15: 3 | E15: ДОПУЩЕНИЕ
A16: K4. Цена рабочего места, ₽/мес | B16: 4900 | E16: ДОПУЩЕНИЕ
A17: K4. Минимум мест | B17: 3 | E17: ДОПУЩЕНИЕ
A18: K4. Технический лимит, стр/место/мес | B18: 2200 | E18: ДОПУЩЕНИЕ
A20: ВЫРУЧКА ПО КОНСТРУКЦИЯМ НА ПЯТИ ПРОФИЛЯХ ПОТРЕБЛЕНИЯ
A21: Профиль | B21: 5 стр/день 110 стр/мес | C21: 20 стр/день 440 стр/мес | D21: 100 стр/день 2 200 стр/мес | E21: 300 стр/день 6 600 стр/мес | F21: 1000 стр/день 22 000 стр/мес | G21: Комментарий
A22: Страниц в месяц | B22: =5*Допущения_и_данные!$B$43 -> 110 | C22: =20*Допущения_и_данные!$B$43 -> 440 | D22: =100*Допущения_и_данные!$B$43 -> 2200 | E22: =300*Допущения_и_данные!$B$43 -> 6600 | F22: =1000*Допущения_и_данные!$B$43 -> 22000
A23: K1. Гибрид: платформа + страницы | B23: =$B$5+$B$6*B22 -> 7780 | C23: =$B$5+$B$6*C22 -> 10420 | D23: =$B$5+$B$6*D22 -> 24500 | E23: =$B$5+$B$6*E22 -> 59700 | F23: =$B$5+$B$6*F22 -> 182900 | G23: Выручка следует за объёмом с первой страницы. Угадывать средний объём не нужно вообще.
A24: K2. Классика: подписка с квотой | B24: =$B$7+MAX(0,B22-$B$8)*$B$9 -> 19900 | C24: =$B$7+MAX(0,C22-$B$8)*$B$9 -> 19900 | D24: =$B$7+MAX(0,D22-$B$8)*$B$9 -> 25500 | E24: =$B$7+MAX(0,E22-$B$8)*$B$9 -> 60700 | F24: =$B$7+MAX(0,F22-$B$8)*$B$9 -> 183900 | G24: Все клиенты до 1 500 стр платят одинаково — это и есть ставка на угаданный средний объём.
A25: K3. Ступени по факту месяца | B25: =$B$10+MIN(MAX(0,B22-$B$11),3000-$B$11)*$B$12+MIN(MAX(0,B22-3000),7000)*$B$13+MIN(MAX(0,B22-10000),20000)*$B$14+MAX(0,B22-30000)*$B$15 -> 9900 | C25: =$B$10+MIN(MAX(0,C22-$B$11),3000-$B$11)*$B$12+MIN(MAX(0,C22-3000),7000)*$B$13+MIN(MAX(0,C22-10000),20000)*$B$14+MAX(0,C22-30000)*$B$15 -> 9900 | D25: =$B$10+MIN(MAX(0,D22-$B$11),3000-$B$11)*$B$12+MIN(MAX(0,D22-3000),7000)*$B$13+MIN(MAX(0,D22-10000),20000)*$B$14+MAX(0,D22-30000)*$B$15 -> 23500 | E25: =$B$10+MIN(MAX(0,E22-$B$11),3000-$B$11)*$B$12+MIN(MAX(0,E22-3000),7000)*$B$13+MIN(MAX(0,E22-10000),20000)*$B$14+MAX(0,E22-30000)*$B$15 -> 51500 | F25: =$B$10+MIN(MAX(0,F22-$B$11),3000-$B$11)*$B$12+MIN(MAX(0,F22-3000),7000)*$B$13+MIN(MAX(0,F22-10000),20000)*$B$14+MAX(0,F22-30000)*$B$15 -> 119900 | G25: Клиент не выбирает тариф. Ступень определяется постфактум по фактическому объёму.
A26: K4. За рабочее место | B26: =$B$16*MAX($B$17,ROUNDUP(B22/$B$18,0)) -> 14700 | C26: =$B$16*MAX($B$17,ROUNDUP(C22/$B$18,0)) -> 14700 | D26: =$B$16*MAX($B$17,ROUNDUP(D22/$B$18,0)) -> 14700 | E26: =$B$16*MAX($B$17,ROUNDUP(E22/$B$18,0)) -> 14700 | F26: =$B$16*MAX($B$17,ROUNDUP(F22/$B$18,0)) -> 49000 | G26: Выручка не зависит от объёма вообще — только от числа людей.
A27: Альтернатива клиента (ручная вычитка), ₽/мес | B27: =B22*Допущения_и_данные!$B$57 -> 4400 | C27: =C22*Допущения_и_данные!$B$57 -> 17600 | D27: =D22*Допущения_и_данные!$B$57 -> 88000 | E27: =E22*Допущения_и_данные!$B$57 -> 264000 | F27: =F22*Допущения_и_данные!$B$57 -> 880000
A29: ЮНИТ-ЭКОНОМИКА КОНСТРУКЦИЙ (поштучная оплата токенов, самая дешёвая модель)
A30: K1. Гибрид | B30: 110 стр | C30: 440 стр | D30: 2 200 стр | E30: 6 600 стр | F30: 22 000 стр
A31: Выручка, ₽/мес | B31: =B23 -> 7780 | C31: =C23 -> 10420 | D31: =D23 -> 24500 | E31: =E23 -> 59700 | F31: =F23 -> 182900
A32: Токены, ₽/мес | B32: =-B22*Себестоимость!$B$29 -> -3.4547275 | C32: =-C22*Себестоимость!$B$29 -> -13.81891 | D32: =-D22*Себестоимость!$B$29 -> -69.09455 | E32: =-E22*Себестоимость!$B$29 -> -207.28365 | F32: =-F22*Себестоимость!$B$29 -> -690.9455
A33: Поддержка (своё время), ₽/мес | B33: =-Допущения_и_данные!$B$56 -> -6000 | C33: =-Допущения_и_данные!$B$56 -> -6000 | D33: =-Допущения_и_данные!$B$56 -> -6000 | E33: =-Допущения_и_данные!$B$56 -> -6000 | F33: =-Допущения_и_данные!$B$56 -> -6000
A34: Валовая маржа, ₽/мес | B34: =B31+B32+B33 -> 1776.5453 | C34: =C31+C32+C33 -> 4406.1811 | D34: =D31+D32+D33 -> 18430.905 | E34: =E31+E32+E33 -> 53492.716 | F34: =F31+F32+F33 -> 176209.05
A35: Валовая маржа, % | B35: =IFERROR(B34/B31,0) -> 0.22834772 | C35: =IFERROR(C34/C31,0) -> 0.42285807 | D35: =IFERROR(D34/D31,0) -> 0.75228186 | E35: =IFERROR(E34/E31,0) -> 0.8960254 | F35: =IFERROR(F34/F31,0) -> 0.96341747
A36: Клиентов до безубыточности | B36: =IF(B34<=0,"никогда",ROUNDUP(Допущения_и_данные!$B$54/B34,0)) -> 5 | C36: =IF(C34<=0,"никогда",ROUNDUP(Допущения_и_данные!$B$54/C34,0)) -> 2 | D36: =IF(D34<=0,"никогда",ROUNDUP(Допущения_и_данные!$B$54/D34,0)) -> 1 | E36: =IF(E34<=0,"никогда",ROUNDUP(Допущения_и_данные!$B$54/E34,0)) -> 1 | F36: =IF(F34<=0,"никогда",ROUNDUP(Допущения_и_данные!$B$54/F34,0)) -> 1
A37: K2. Классика с квотой | B37: 110 стр | C37: 440 стр | D37: 2 200 стр | E37: 6 600 стр | F37: 22 000 стр
A38: Выручка, ₽/мес | B38: =B24 -> 19900 | C38: =C24 -> 19900 | D38: =D24 -> 25500 | E38: =E24 -> 60700 | F38: =F24 -> 183900
A39: Токены, ₽/мес | B39: =-B22*Себестоимость!$B$29 -> -3.4547275 | C39: =-C22*Себестоимость!$B$29 -> -13.81891 | D39: =-D22*Себестоимость!$B$29 -> -69.09455 | E39: =-E22*Себестоимость!$B$29 -> -207.28365 | F39: =-F22*Себестоимость!$B$29 -> -690.9455
A40: Поддержка (своё время), ₽/мес | B40: =-Допущения_и_данные!$B$56 -> -6000 | C40: =-Допущения_и_данные!$B$56 -> -6000 | D40: =-Допущения_и_данные!$B$56 -> -6000 | E40: =-Допущения_и_данные!$B$56 -> -6000 | F40: =-Допущения_и_данные!$B$56 -> -6000
A41: Валовая маржа, ₽/мес | B41: =B38+B39+B40 -> 13896.545 | C41: =C38+C39+C40 -> 13886.181 | D41: =D38+D39+D40 -> 19430.905 | E41: =E38+E39+E40 -> 54492.716 | F41: =F38+F39+F40 -> 177209.05
A42: Валовая маржа, % | B42: =IFERROR(B41/B38,0) -> 0.69831886 | C42: =IFERROR(C41/C38,0) -> 0.69779804 | D42: =IFERROR(D41/D38,0) -> 0.76199629 | E42: =IFERROR(E41/E38,0) -> 0.89773833 | F42: =IFERROR(F41/F38,0) -> 0.96361639
A43: Клиентов до безубыточности | B43: =IF(B41<=0,"никогда",ROUNDUP(Допущения_и_данные!$B$54/B41,0)) -> 1 | C43: =IF(C41<=0,"никогда",ROUNDUP(Допущения_и_данные!$B$54/C41,0)) -> 1 | D43: =IF(D41<=0,"никогда",ROUNDUP(Допущения_и_данные!$B$54/D41,0)) -> 1 | E43: =IF(E41<=0,"никогда",ROUNDUP(Допущения_и_данные!$B$54/E41,0)) -> 1 | F43: =IF(F41<=0,"никогда",ROUNDUP(Допущения_и_данные!$B$54/F41,0)) -> 1
...

Sheet Выводы
B1: ВЫВОДЫ И РЕКОМЕНДАЦИЯ
B3: 1. СЕБЕСТОИМОСТЬ
B4: Диапазон по всем моделям — от 0.0314 ₽ за страницу (Gemma 4 26B A4B с кэшем) до 0.161 ₽ (Qwen3.5-27B без кэша), разброс 5.1 раза. Три измеренных документа: от 0.09 до 0.84 ₽ на Gemma 26B с кэшем и от 0.45 до 4.40 ₽ на Qwen 27B без кэша.
B5: Вход даёт 74–89% расхода — прямое следствие измеренного соотношения 23:1. Выбирать модель надо по цене входа и цене чтения кэша.
B6: Кэширование даёт 31% экономии на Gemma 26B, но только 9.5% на Gemma 31B: у неё чтение кэша стоит 11.09 против входа 14.79, скидка всего 25% против 90% у остальных. Кэш выгоден не сам по себе, а только там, где поставщик даёт по нему настоящую скидку.
B7: Ваши прежние 0.083 ₽/стр — это ровно Gemma 4 31B без кэша, а 0.031 ₽/стр — Gemma 4 26B A4B с кэшем. Две независимые выгрузки сошлись.
B8: 2. ФИКСИРОВАННЫЕ 30 000 ₽ НЕВЫГОДНЫ НИ ПРИ КАКОМ РЕАЛИСТИЧНОМ ОБЪЁМЕ
B9: Порог перехода — от 186 тыс. страниц в месяц на самой дорогой модели до 955 тыс. на самой дешёвой. Верхняя граница физически недостижима: месячная мощность сервиса при 8-часовом дне составляет 757 тыс. страниц. То есть на Gemma 26B с кэшем фиксированная плата не окупится никогда — раньше кончится железо.
B10: Нижняя граница (186 тыс. страниц) требует 84 клиентов, каждый из которых обрабатывает 100 страниц в день. Переход на поштучную оплату экономит почти все 30 000 ₽ в месяц при объёмах первых клиентов.
B11: 3. РАЗБРОС ПОТРЕБЛЕНИЯ НА НАС ПОЧТИ НЕ ВЛИЯЕТ, А НА КЛИЕНТА ВЛИЯЕТ ПОЛНОСТЬЮ
B12: От 5 до 1000 страниц в день — разброс в 200 раз. Расход на токены при этом меняется от 3 до 3 554 ₽ в месяц. Даже верхняя граница меньше, чем два часа вашей поддержки. Наши расходы к объёму почти нечувствительны.
B13: У клиента то же изменение объёма меняет ценность от 4 400 до 880 000 ₽ сэкономленного ручного труда в месяц. Отсюда принцип: цена должна следовать за объёмом не потому, что объём нам дорого обходится, а потому, что объём — это мера полученной пользы.
... B32: Восемь вопросов, ответы на которые уточнят расчёт, перечислены внизу листа «Допущения_и_данные». Самые важные — первый (есть ли кэширование вообще) и четвёртый (реальные часы поддержки): они меняют не точность, а выводы.
